Workbook

Sheet Jan
A2: 502 OSS/OSW LACKLAND AFB, KELLY ANNEX, TX
A3: DAILY CLIMATOLOGICAL DATA
A4: FOR
A5: JANUARY 2025
B7: TEMPERATURE | G7: PRECIPITATION | I7: WIND
D8: DEGREE DAYS | G8: WATER | H8: DAILY
D9: BASE = 65 | G9: EQUIV- | H9: SNOW | I9: MAX | J9: DIREC-
A10: DAY | B10: MAX | C10: MIN | D10: MEAN | E10: HEATING | F10: COOLING | G10: ALENT | H10: FALL | I10: SPEED | J10: TION
A12: 1 | B12: 63 | C12: 47 | D12: =(B12+C12)/2 -> 55 | E12: =IF(65-D12>0,65-M12,0) -> 10 | F12: =IF((D12)-65<0,0,(D12)-65) -> 0 | G12: 0 | H12: 0 | I12: 22 | J12: 50 | M12: =IF(D12=0,65,D12) -> 55
A13: 2 | B13: 63 | C13: 47 | D13: =(B13+C13)/2 -> 55 | E13: =IF(65-D13>0,65-M13,0) -> 10 | F13: =IF((D13)-65<0,0,(D13)-65) -> 0 | G13: 0 | H13: 0 | I13: 11 | J13: 10 | M13: =IF(D13=0,65,D13) -> 55
A14: 3 | B14: 67 | C14: 49 | D14: =(B14+C14)/2 -> 58 | E14: =IF(65-D14>0,65-M14,0) -> 7 | F14: =IF((D14)-65<0,0,(D14)-65) -> 0 | G14: 0 | H14: 0 | I14: 13 | J14: 50 | M14: =IF(D14=0,65,D14) -> 58
A15: 4 | B15: 75 | C15: 61 | D15: =(B15+C15)/2 -> 68 | E15: =IF(65-D15>0,65-M15,0) -> 0 | F15: =IF((D15)-65<0,0,(D15)-65) -> 3 | G15: 0 | H15: 0 | I15: 20 | J15: 30 | M15: =IF(D15=0,65,D15) -> 68
A16: 5 | B16: 79 | C16: 43 | D16: =(B16+C16)/2 -> 61 | E16: =IF(65-D16>0,65-M16,0) -> 4 | F16: =IF((D16)-65<0,0,(D16)-65) -> 0 | G16: 0 | H16: 0 | I16: 23 | J16: 360 | M16: =IF(D16=0,65,D16) -> 61
A17: 6 | B17: 52 | C17: 32 | D17: =(B17+C17)/2 -> 42 | E17: =IF(65-D17>0,65-M17,0) -> 23 | F17: =IF((D17)-65<0,0,(D17)-65) -> 0 | G17: 0 | H17: 0 | I17: 28 | J17: 360 | M17: =IF(D17=0,65,D17) -> 42
A18: 7 | B18: 52 | C18: 30 | D18: =(B18+C18)/2 -> 41 | E18: =IF(65-D18>0,65-M18,0) -> 24 | F18: =IF((D18)-65<0,0,(D18)-65) -> 0 | G18: 0 | H18: 0 | I18: 18 | J18: 40 | M18: =IF(D18=0,65,D18) -> 41
A19: 8 | B19: 45 | C19: 37 | D19: =(B19+C19)/2 -> 41 | E19: =IF(65-D19>0,65-M19,0) -> 24 | F19: =IF((D19)-65<0,0,(D19)-65) -> 0 | G19: 0 | H19: 0 | I19: 19 | J19: 20 | M19: =IF(D19=0,65,D19) -> 41
A20: 9 | B20: 42 | C20: 37 | D20: =(B20+C20)/2 -> 39.5 | E20: =IF(65-D20>0,65-M20,0) -> 25.5 | F20: =IF((D20)-65<0,0,(D20)-65) -> 0 | G20: 0.88 | H20: 0 | I20: 19 | J20: 360 | M20: =IF(D20=0,65,D20) -> 39.5
A21: 10 | B21: 48 | C21: 33 | D21: =(B21+C21)/2 -> 40.5 | E21: =IF(65-D21>0,65-M21,0) -> 24.5 | F21: =IF((D21)-65<0,0,(D21)-65) -> 0 | G21: 0 | H21: 0 | I21: 33 | J21: 340 | M21: =IF(D21=0,65,D21) -> 40.5
A22: 11 | B22: 59 | C22: 26 | D22: =(B22+C22)/2 -> 42.5 | E22: =IF(65-D22>0,65-M22,0) -> 22.5 | F22: =IF((D22)-65<0,0,(D22)-65) -> 0 | G22: 0 | H22: 0 | I22: 19 | J22: 170 | M22: =IF(D22=0,65,D22) -> 42.5
A23: 12 | B23: 66 | C23: 31 | D23: =(B23+C23)/2 -> 48.5 | E23: =IF(65-D23>0,65-M23,0) -> 16.5 | F23: =IF((D23)-65<0,0,(D23)-65) -> 0 | G23: 0 | H23: 0 | I23: 17 | J23: 350 | M23: =IF(D23=0,65,D23) -> 48.5
... A42: 31 | B42: 77 | C42: 45 | D42: =(B42+C42)/2 -> 61 | E42: =IF(65-D42>0,65-M42,0) -> 4 | F42: =IF((D42)-65<0,0,(D42)-65) -> 0 | G42: 0 | H42: 0 | I42: 18 | J42: 320 | M42: =IF(D42=0,65,D42) -> 61
A43: TOTAL | B43: N/A | C43: N/A | D43: =SUM(D12:D42) -> 1550 | E43: =SUM(E12:E42) -> 468 | F43: =SUM(F12:F42) -> 3 | G43: =SUM(G12:G42) -> 0.91 | H43: =SUM(H12:H42) -> 0 | I43: N/A | J43: N/A | M43: =IF(D43=0,65,D43) -> 1550 | O43: =SUM(G12:G30) -> 0.88
A44: EXTREME | B44: =MAXA(B12:B42) -> 79 | C44: =MINA(C12:C42) -> 23 | D44: =(B44+C44)/2 -> 51 | E44: =IF(65-D44>0,65-M44,0) -> 65 | F44: =IF((D44)-65<0,0,(D44)-65) -> 0 | G44: =MAXA(G12:G42) -> 0.88 | H44: =MAXA(H13:H42) -> 0 | I44: =MAXA(I12:I42) -> 33 | J44: 340
A45: MEAN | B45: =IF(ISERROR(AVERAGEA(B12:B42)),"NO DATA",(AVERAGE(B12:B42))) -> 59.774194 | C45: =IF(ISERROR(AVERAGEA(C12:C42)),"NO DATA",(AVERAGE(C12:C42))) -> 40.225806 | D45: =IF(ISERROR(AVERAGEA(D12:D42)),"NO DATA",(AVERAGE(D12:D42))) -> 50 | E45: 65 | F45: =IF((D45)-65<0,0,(D45)-65) -> 0 | G45: =IF(ISERROR(AVERAGEA(G12:G42)),"NO DATA",(AVERAGE(G12:G42))) -> 0.029354839 | H45: =AVERAGEA(H12:H42) -> 0 | I45: =IF(ISERROR(AVERAGEA(I12:I42)),"NO DATA",(AVERAGE(I12:I42))) -> 19.548387 | J45: =IF(ISERROR(AVERAGEA(J12:J42)),"NO DATA",(AVERAGE(J12:J42))) -> 125.16129
A46: CLIMO. | B46: 91 | C46: 4 | D46: 53 | E46: =AVERAGEA(E13:E42) -> 15.266667 | F46: =AVERAGEA(F13:F42) -> 0.1 | G46: 1.5 | H46: 0.3 | I46: 6 | J46: 360
A47: PRECIPITATION ABOVE CLIMO. | G47: =(G43-G46) -> -0.59
A48: NOTE: CLIMO. TEMPERATURES ARE EXTREMES.
B53: TEMPERATURE | G53: PRECIP. | J53: WIND
B54: EXTRME MAX | C54: MEAN MAX | D54: MEAN | E54: MEAN MIN | F54: EXTRME MIN | G54: MAX | H54: MEAN | I54: 24 HR MAX | J54: MAX
A55: FROM ABOVE | B55: =MAXA(B12:B42) -> 79 | C55: 60 | D55: =IF(ISERROR(AVERAGEA(D12:D42)),"NO DATA",(AVERAGE(D12:D42))) -> 50 | E55: =IF(ISERROR(AVERAGEA(C12:C42)),"NO DATA",(AVERAGE(C12:C42))) -> 40.225806 | F55: =MINA(C12:C42) -> 23 | G55: =SUM(G11:G42) -> 0.91 | H55: =AVERAGE(G11:G42) -> 0.029354839 | I55: =MAXA(G12:G42) -> 0.88 | J55: =MAXA(I12:I42) -> 33
A56: CLIMO | B56: 91 | C56: 66 | D56: 53 | E56: 42 | F56: 4 | G56: 9 | H56: 1.5 | I56: 3.5 | J56: 57

Sheet Feb 
A1: 502 OSS/OSW LACKLAND AFB, KELLY ANNEX, TX
A2: DAILY CLIMATOLOGICAL DATA
A3: FOR
A4: FEBRUARY 2025
B6: TEMPERATURE | G6: PRECIPITATION | I6: WIND
D7: DEGREE DAYS | G7: WATER | H7: DAILY
D8: BASE = 65 | G8: EQUIV- | H8: SNOW | I8: MAX | J8: DIREC-
A9: DAY | B9: MAX | C9: MIN | D9: MEAN | E9: HEATING | F9: COOLING | G9: ALENT | H9: FALL | I9: SPEED | J9: TION
A11: 1 | B11: 78 | C11: 37 | D11: =(B11+C11)/2 -> 57.5 | E11: =IF(65-D11>0,65-M11,0) -> 7.5 | F11: =IF((D11)-65<0,0,(D11)-65) -> 0 | G11: 0 | H11: 0 | I11: 14 | J11: 180 | M11: =IF(D11=0,65,D11) -> 57.5
A12: 2 | B12: 83 | C12: 42 | D12: =(B12+C12)/2 -> 62.5 | E12: =IF(65-D12>0,65-M12,0) -> 2.5 | F12: =IF((D12)-65<0,0,(D12)-65) -> 0 | G12: 0 | H12: 0 | I12: 18 | J12: 190 | M12: =IF(D12=0,65,D12) -> 62.5
A13: 3 | B13: 87 | C13: 55 | D13: =(B13+C13)/2 -> 71 | E13: =IF(65-D13>0,65-M13,0) -> 0 | F13: =IF((D13)-65<0,0,(D13)-65) -> 6 | G13: 0 | H13: 0 | I13: 18 | J13: 150 | M13: =IF(D13=0,65,D13) -> 71
A14: 4 | B14: 85 | C14: 64 | D14: =(B14+C14)/2 -> 74.5 | E14: =IF(65-D14>0,65-M14,0) -> 0 | F14: =IF((D14)-65<0,0,(D14)-65) -> 9.5 | G14: 0 | H14: 0.2 | I14: 20 | J14: 120 | M14: =IF(D14=0,65,D14) -> 74.5
A15: 5 | B15: 81 | C15: 65 | D15: =(B15+C15)/2 -> 73 | E15: =IF(65-D15>0,65-M15,0) -> 0 | F15: =IF((D15)-65<0,0,(D15)-65) -> 8 | G15: 0 | H15: 0 | I15: 13 | J15: 150 | M15: =IF(D15=0,65,D15) -> 73
A16: 6 | B16: 86 | C16: 64 | D16: =(B16+C16)/2 -> 75 | E16: =IF(65-D16>0,65-M16,0) -> 0 | F16: =IF((D16)-65<0,0,(D16)-65) -> 10 | G16: 0 | H16: 0 | I16: 17 | J16: 140 | M16: =IF(D16=0,65,D16) -> 75
A17: 7 | B17: 86 | C17: 69 | D17: =(B17+C17)/2 -> 77.5 | E17: =IF(65-D17>0,65-M17,0) -> 0 | F17: =IF((D17)-65<0,0,(D17)-65) -> 12.5 | G17: 0 | H17: 0 | I17: 22 | J17: 130 | M17: =IF(D17=0,65,D17) -> 77.5
A18: 8 | B18: 91 | C18: 68 | D18: =(B18+C18)/2 -> 79.5 | E18: =IF(65-D18>0,65-M18,0) -> 0 | F18: =IF((D18)-65<0,0,(D18)-65) -> 14.5 | G18: 0 | H18: 0 | I18: 23 | J18: 140 | M18: =IF(D18=0,65,D18) -> 79.5
A19: 9 | B19: 72 | C19: 57 | D19: =(B19+C19)/2 -> 64.5 | E19: =IF(65-D19>0,65-M19,0) -> 0.5 | F19: =IF((D19)-65<0,0,(D19)-65) -> 0 | G19: 0 | H19: 0 | I19: 19 | J19: 30 | M19: =IF(D19=0,65,D19) -> 64.5
A20: 10 | B20: 57 | C20: 50 | D20: =(B20+C20)/2 -> 53.5 | E20: =IF(65-D20>0,65-M20,0) -> 11.5 | F20: =IF((D20)-65<0,0,(D20)-65) -> 0 | G20: 0 | H20: 0 | I20: 17 | J20: 30 | M20: =IF(D20=0,65,D20) -> 53.5
A21: 11 | B21: 60 | C21: 51 | D21: =(B21+C21)/2 -> 55.5 | E21: =IF(65-D21>0,65-M21,0) -> 9.5 | F21: =IF((D21)-65<0,0,(D21)-65) -> 0 | G21: 0.24 | H21: 0 | I21: 19 | J21: 50 | M21: =IF(D21=0,65,D21) -> 55.5
A22: 12 | B22: 71 | C22: 45 | D22: =(B22+C22)/2 -> 58 | E22: =IF(65-D22>0,65-M22,0) -> 7 | F22: =IF((D22)-65<0,0,(D22)-65) -> 0 | G22: 0.08 | H22: 0 | I22: 26 | J22: 20 | M22: =IF(D22=0,65,D22) -> 58
... A38: 28 | B38: 79 | C38: 45 | D38: =(B38+C38)/2 -> 62 | E38: =IF(65-D38>0,65-M38,0) -> 3 | F38: =IF((D38)-65<0,0,(D38)-65) -> 0 | G38: 0 | H38: 0 | I38: 11 | J38: 190 | M38: =IF(D38=0,65,D38) -> 62
A39: 29 | D39: =(B39+C39)/2 -> 0 | E39: =IF(65-D39>0,65-M39,0) -> 0 | F39: 5 | G39: 0 | H39: 0 | M39: =IF(D39=0,65,D39) -> 65
A40: 29 | D40: =(B40+C40)/2 -> 0 | E40: =IF(65-D40>0,65-M40,0) -> 0 | F40: =IF((D40)-65<0,0,(D40)-65) -> 0 | H40: 0 | M40: =IF(D40=0,65,D40) -> 65
A41: TOTAL | B41: N/A | C41: N/A | D41: =SUM(D11:D40) -> 1616.5 | E41: =SUM(E11:E40) -> 269 | F41: =SUM(F11:F40) -> 70.5 | G41: =SUM(G11:G40) -> 0.4 | H41: =SUM(H11:H40) -> 0.2 | I41: N/A | J41: N/A | M41: =IF(D41=0,65,D41) -> 1616.5
A42: EXTREME | B42: =MAXA(B11:B39) -> 91 | C42: =MINA(C11:C39) -> 23 | D42: =(B42+C42)/2 -> 57 | E42: =IF(65-D42>0,65-M42,0) -> 65 | F42: =IF((D42)-65<0,0,(D42)-65) -> 0 | G42: =MAXA(G11:G39) -> 0.24 | H42: =MAXA(H11:H39) -> 0.2 | I42: =MAXA(I11:I39) -> 33 | J42: 360
A43: MEAN | B43: =IF(ISERROR(AVERAGEA(B11:B39)),"NO DATA",(AVERAGE(B11:B39))) -> 69.071429 | C43: =IF(ISERROR(AVERAGEA(C11:C39)),"NO DATA",(AVERAGE(C11:C39))) -> 46.392857 | D43: =(B43+C43)/2 -> 57.732143 | E43: =IF(65-D43>0,65-M43,0) -> 65 | F43: =IF((D43)-65<0,0,(D43)-65) -> 0 | G43: =IF(ISERROR(AVERAGEA(G11:G39)),"NO DATA",(AVERAGE(G11:G39))) -> 0.013793103 | H43: =AVERAGEA(H11:H39) -> 0.0068965517 | I43: =IF(ISERROR(AVERAGEA(I11:I39)),"NO DATA",(AVERAGE(I11:I39))) -> 18.857143 | J43: =IF(ISERROR(AVERAGEA(J11:J39)),"NO DATA",(AVERAGE(J11:J39))) -> 124.28571
A44: CLIMO. | B44: 100 | C44: 9 | D44: 55 | E44: =AVERAGEA(E12:E40) -> 9.0172414 | F44: =AVERAGEA(F12:F40) -> 2.4310345 | G44: 1.6 | H44: 0.2 | I44: 10 | J44: 20
A45: PRECIPITATION ABOVE CLIMO. | G45: =SUM(G11:G39)-G44 -> -1.2
A46: NOTE: CLIMO. TEMPERATURES ARE EXTREMES. "T" IN SNOWFALL IS BOTH SNOW AND SLEET.
B52: TEMPERATURE | G52: PRECIP. | J52: WIND
B53: EXTRME MAX | C53: MEAN MAX | D53: MEAN | E53: MEAN MIN | F53: EXTRME MIN | G53: MAX | H53: MEAN | I53: 24 HR MAX | J53: MAX
A54: FROM ABOVE | B54: =MAXA(B11:B39) -> 91 | C54: =IF(ISERROR(AVERAGEA(B11:B39)),"NO DATA",(AVERAGE(B11:B39))) -> 69.071429 | D54: =(B43+C43)/2 -> 57.732143 | E54: =IF(ISERROR(AVERAGEA(C11:C40)),"NO DATA",(AVERAGE(C11:C40))) -> 46.392857 | F54: =MINA(C11:C40) -> 23 | G54: =SUM(G11:G39) -> 0.4 | H54: =AVERAGE(G11:G39) -> 0.013793103 | I54: =MAXA(G11:G40) -> 0.24 | J54: =MAXA(I11:I40) -> 33
A55: CLIMO | B55: 100 | C55: 69 | D55: 55 | E55: 46 | F55: 9 | G55: 6.8 | H55: 1.6 | I55: 2.4 | J55: 50

Sheet Mar
A2: 502 OSS/OSW LACKLAND AFB, KELLY ANNEX, TX
A3: DAILY CLIMATOLOGICAL DATA
A4: FOR
A5: MARCH 2025
B7: TEMPERATURE | G7: PRECIPITATION | I7: WIND
D8: DEGREE DAYS | G8: WATER | H8: DAILY
D9: BASE = 65 | G9: EQUIV- | H9: SNOW | I9: MAX | J9: DIREC-
A10: DAY | B10: MAX | C10: MIN | D10: MEAN | E10: HEATING | F10: COOLING | G10: ALENT | H10: FALL | I10: SPEED | J10: TION
A12: 1 | B12: 85 | C12: 48 | D12: =(B12+C12)/2 -> 66.5 | E12: =IF(65-D12>0,65-M12,0) -> 0 | F12: =IF((D12)-65<0,0,(D12)-65) -> 1.5 | G12: 0 | H12: 0 | I12: 16 | J12: 140 | M12: =IF(D12=0,65,D12) -> 66.5
A13: 2 | B13: 86 | C13: 61 | D13: =(B13+C13)/2 -> 73.5 | E13: =IF(65-D13>0,65-M13,0) -> 0 | F13: =IF((D13)-65<0,0,(D13)-65) -> 8.5 | G13: 0 | H13: 0 | I13: 30 | J13: 140 | M13: =IF(D13=0,65,D13) -> 73.5
A14: 3 | B14: 72 | C14: 65 | D14: =(B14+C14)/2 -> 68.5 | E14: =IF(65-D14>0,65-M14,0) -> 0 | F14: =IF((D14)-65<0,0,(D14)-65) -> 3.5 | G14: 0 | H14: 0 | I14: 24 | J14: 150 | M14: =IF(D14=0,65,D14) -> 68.5
A15: 4 | B15: 78 | C15: 56 | D15: =(B15+C15)/2 -> 67 | E15: =IF(65-D15>0,65-M15,0) -> 0 | F15: =IF((D15)-65<0,0,(D15)-65) -> 2 | G15: 0.05 | H15: 0 | I15: 41 | J15: 290 | M15: =IF(D15=0,65,D15) -> 67
A16: 5 | B16: 76 | C16: 56 | D16: =(B16+C16)/2 -> 66 | E16: =IF(65-D16>0,65-M16,0) -> 0 | F16: =IF((D16)-65<0,0,(D16)-65) -> 1 | G16: 0 | H16: 0 | I16: 20 | J16: 360 | M16: =IF(D16=0,65,D16) -> 66
A17: 6 | B17: 80 | C17: 44 | D17: =(B17+C17)/2 -> 62 | E17: =IF(65-D17>0,65-M17,0) -> 3 | F17: =IF((D17)-65<0,0,(D17)-65) -> 0 | G17: 0 | H17: 0 | I17: 30 | J17: 140 | M17: =IF(D17=0,65,D17) -> 62
A18: 7 | B18: 87 | C18: 64 | D18: =(B18+C18)/2 -> 75.5 | E18: =IF(65-D18>0,65-M18,0) -> 0 | F18: =IF((D18)-65<0,0,(D18)-65) -> 10.5 | G18: 0 | H18: 0 | I18: 20 | J18: 120 | M18: =IF(D18=0,65,D18) -> 75.5
A19: 8 | B19: 90 | C19: 52 | D19: =(B19+C19)/2 -> 71 | E19: =IF(65-D19>0,65-M19,0) -> 0 | F19: =IF((D19)-65<0,0,(D19)-65) -> 6 | G19: 0 | H19: 0 | I19: 37 | J19: 350 | M19: =IF(D19=0,65,D19) -> 71
A20: 9 | B20: 69 | C20: 44 | D20: =(B20+C20)/2 -> 56.5 | E20: =IF(65-D20>0,65-M20,0) -> 8.5 | F20: =IF((D20)-65<0,0,(D20)-65) -> 0 | G20: 0 | H20: 0 | I20: 26 | J20: 330 | M20: =IF(D20=0,65,D20) -> 56.5
A21: 10 | B21: 78 | C21: 38 | D21: =(B21+C21)/2 -> 58 | E21: =IF(65-D21>0,65-M21,0) -> 7 | F21: =IF((D21)-65<0,0,(D21)-65) -> 0 | G21: 0 | H21: 0 | I21: 16 | J21: 230 | M21: =IF(D21=0,65,D21) -> 58
A22: 11 | B22: 86 | C22: 42 | D22: =(B22+C22)/2 -> 64 | E22: =IF(65-D22>0,65-M22,0) -> 1 | F22: =IF((D22)-65<0,0,(D22)-65) -> 0 | G22: 0 | H22: 0 | I22: 19 | J22: 160 | M22: =IF(D22=0,65,D22) -> 64
A23: 12 | B23: 94 | C23: 55 | D23: =(B23+C23)/2 -> 74.5 | E23: =IF(65-D23>0,65-M23,0) -> 0 | F23: =IF((D23)-65<0,0,(D23)-65) -> 9.5 | G23: 0 | H23: 0 | I23: 23 | J23: 240 | M23: =IF(D23=0,65,D23) -> 74.5
... A42: 31 | B42: 89 | C42: 68 | D42: =(B42+C42)/2 -> 78.5 | E42: =IF(65-D42>0,65-M42,0) -> 0 | F42: =IF((D42)-65<0,0,(D42)-65) -> 13.5 | G42: 0.37 | H42: 0 | I42: 32 | J42: 320 | M42: =IF(D42=0,65,D42) -> 78.5
A43: TOTAL | B43: N/A | C43: N/A | D43: =SUM(D12:D42) -> 2164 | E43: =SUM(E12:E42) -> 29.5 | F43: =SUM(F12:F42) -> 178.5 | G43: =SUM(G12:G42) -> 2.59 | H43: 0 | I43: N/A | J43: N/A | M43: =IF(D43=0,65,D43) -> 2164
A44: EXTREME | B44: =MAXA(B12:B42) -> 97 | C44: =MINA(C12:C42) -> 38 | D44: =(B44+C44)/2 -> 67.5 | E44: =IF(65-D44>0,65-M44,0) -> 0 | F44: =IF((D44)-65<0,0,(D44)-65) -> 2.5 | G44: =MAXA(G12:G42) -> 1.04 | H44: 0 | I44: =MAXA(I12:I42) -> 41 | J44: 290
A45: MEAN | B45: =AVERAGEA(B12:B42) -> 83.870968 | C45: =AVERAGEA(C12:C42) -> 55.741935 | D45: =(B45+C45)/2 -> 69.806452 | E45: =IF(65-D45>0,65-M45,0) -> 0 | F45: =IF((D45)-65<0,0,(D45)-65) -> 4.8064516 | G45: =AVERAGEA(G12:G42) -> 0.083548387 | H45: =AVERAGEA(H12:H42) -> 0 | I45: =AVERAGEA(I12:I42) -> 24.451613 | J45: =AVERAGEA(J12:J42) -> 191.29032
A46: CLIMO. | B46: 101 | C46: 21 | D46: 65 | E46: =AVERAGEA(E13:E42) -> 0.98333333 | F46: =AVERAGEA(F13:F42) -> 5.9 | G46: 1.6 | H46: N/A | I46: 9 | J46: 140
A47: PRECIPITATION ABOVE CLIMO. | G47: =(G43-G46) -> 0.99
A48: NOTE: CLIMO. TEMPERATURES ARE EXTREMES. | H48: * = HAIL
B52: TEMPERATURE | G52: PRECIP. | J52: WIND
B53: EXTRME MAX | C53: MEAN MAX | D53: MEAN | E53: MEAN MIN | F53: EXTRME MIN | G53: MAX | H53: MEAN | I53: 24 HR MAX | J53: MAX
A54: FROM ABOVE | B54: =MAXA(B12:B42) -> 97 | C54: =AVERAGEA(B12:B42) -> 83.870968 | D54: =(B45+C45)/2 -> 69.806452 | E54: =AVERAGEA(C12:C42) -> 55.741935 | F54: =MINA(C12:C42) -> 38 | G54: =SUM(G12:G40) -> 2.21 | H54: =AVERAGEA(G12:G42) -> 0.083548387 | I54: =MAXA(G12:G40) -> 1.04 | J54: =MAXA(I12:I40) -> 41
A55: CLIMO | B55: 101 | C55: 76 | D55: 65 | E55: 55 | F55: 21 | G55: 6.6 | H55: 1.6 | I55: 3.3 | J55: 58

Sheet Apr 
A2: 502 OSS/OSW LACKLAND AFB, KELLY ANNEX, TX
A3: DAILY CLIMATOLOGICAL DATA
A4: FOR
A5: APRIL 2025
B7: TEMPERATURE | G7: PRECIPITATION | I7: WIND
D8: DEGREE DAYS | G8: WATER | H8: DAILY
D9: BASE = 65 | G9: EQUIV- | H9: SNOW | I9: MAX | J9: DIREC-
A10: DAY | B10: MAX | C10: MIN | D10: MEAN | E10: HEATING | F10: COOLING | G10: ALENT | H10: FALL | I10: SPEED | J10: TION
A12: 1 | B12: 88 | C12: 67 | D12: =(B12+C12)/2 -> 77.5 | E12: =IF(65-D12>0,65-M12,0) -> 0 | F12: =IF((D12)-65<0,0,(D12)-65) -> 12.5 | G12: 0 | H12: 0 | I12: 26 | J12: 140 | M12: =IF(D12=0,65,D12) -> 77.5
A13: 2 | B13: 90 | C13: 74 | D13: =(B13+C13)/2 -> 82 | E13: =IF(65-D13>0,65-M13,0) -> 0 | F13: =IF((D13)-65<0,0,(D13)-65) -> 17 | G13: 0 | H13: 0 | I13: 18 | J13: 170 | M13: =IF(D13=0,65,D13) -> 82
A14: 3 | B14: 94 | C14: 75 | D14: =(B14+C14)/2 -> 84.5 | E14: =IF(65-D14>0,65-M14,0) -> 0 | F14: =IF((D14)-65<0,0,(D14)-65) -> 19.5 | G14: 0 | H14: 0 | I14: 24 | J14: 120 | M14: =IF(D14=0,65,D14) -> 84.5
A15: 4 | B15: 92 | C15: 76 | D15: =(B15+C15)/2 -> 84 | E15: =IF(65-D15>0,65-M15,0) -> 0 | F15: =IF((D15)-65<0,0,(D15)-65) -> 19 | G15: 0.05 | H15: 0 | I15: 25 | J15: 130 | M15: =IF(D15=0,65,D15) -> 84
A16: 5 | B16: 77 | C16: 53 | D16: =(B16+C16)/2 -> 65 | E16: =IF(65-D16>0,65-M16,0) -> 0 | F16: =IF((D16)-65<0,0,(D16)-65) -> 0 | G16: 0.14 | H16: 0 | I16: 32 | J16: 340 | M16: =IF(D16=0,65,D16) -> 65
A17: 6 | B17: 63 | C17: 46 | D17: =(B17+C17)/2 -> 54.5 | E17: =IF(65-D17>0,65-M17,0) -> 10.5 | F17: =IF((D17)-65<0,0,(D17)-65) -> 0 | G17: 0 | H17: 0 | I17: 30 | J17: 330 | M17: =IF(D17=0,65,D17) -> 54.5
A18: 7 | B18: 75 | C18: 40 | D18: =(B18+C18)/2 -> 57.5 | E18: =IF(65-D18>0,65-M18,0) -> 7.5 | F18: =IF((D18)-65<0,0,(D18)-65) -> 0 | G18: 0 | H18: 0 | I18: 18 | J18: 360 | M18: =IF(D18=0,65,D18) -> 57.5
A19: 8 | B19: 82 | C19: 42 | D19: =(B19+C19)/2 -> 62 | E19: =IF(65-D19>0,65-M19,0) -> 3 | F19: =IF((D19)-65<0,0,(D19)-65) -> 0 | G19: 0 | H19: 0 | I19: 17 | J19: 150 | M19: =IF(D19=0,65,D19) -> 62
A20: 9 | B20: 88 | C20: 51 | D20: =(B20+C20)/2 -> 69.5 | E20: =IF(65-D20>0,65-M20,0) -> 0 | F20: =IF((D20)-65<0,0,(D20)-65) -> 4.5 | G20: 0 | H20: 0 | I20: 20 | J20: 140 | M20: =IF(D20=0,65,D20) -> 69.5
A21: 10 | B21: 91 | C21: 54 | D21: =(B21+C21)/2 -> 72.5 | E21: =IF(65-D21>0,65-M21,0) -> 0 | F21: =IF((D21)-65<0,0,(D21)-65) -> 7.5 | G21: 0 | H21: 0 | I21: 17 | J21: 130 | M21: =IF(D21=0,65,D21) -> 72.5
A22: 11 | B22: 91 | C22: 60 | D22: =(B22+C22)/2 -> 75.5 | E22: =IF(65-D22>0,65-M22,0) -> 0 | F22: =IF((D22)-65<0,0,(D22)-65) -> 10.5 | G22: 0 | H22: 0 | I22: 16 | J22: 180 | M22: =IF(D22=0,65,D22) -> 75.5
A23: 12 | B23: 92 | C23: 58 | D23: =(B23+C23)/2 -> 75 | E23: =IF(65-D23>0,65-M23,0) -> 0 | F23: =IF((D23)-65<0,0,(D23)-65) -> 10 | G23: 0 | H23: 0 | I23: 27 | J23: 170 | M23: =IF(D23=0,65,D23) -> 75
... A41: 30 | B41: 92 | C41: 73 | D41: =(B41+C41)/2 -> 82.5 | E41: =IF(65-D41>0,65-M41,0) -> 0 | F41: =IF((D41)-65<0,0,(D41)-65) -> 17.5 | G41: 0 | H41: 0 | I41: 28 | J41: 140 | M41: =IF(D41=0,65,D41) -> 82.5
A42: TOTAL | B42: N/A | C42: N/A | D42: =SUM(D12:D41) -> 2256.5 | E42: =SUM(E12:E41) -> 21 | F42: =SUM(F12:F41) -> 327.5 | G42: =SUM(G12:G41) -> 1.16 | H42: 0 | I42: N/A | J42: N/A | M42: =IF(D42=0,65,D42) -> 2256.5
A43: EXTREME | B43: =MAXA(B12:B41) -> 94 | C43: =MINA(C12:C41) -> 40 | D43: =(B43+C43)/2 -> 67 | E43: =IF(65-D43>0,65-M43,0) -> 0 | F43: =IF((D43)-65<0,0,(D43)-65) -> 2 | G43: =MAXA(G12:G41) -> 0.8 | H43: 0 | I43: =MAXA(I12:I41) -> 33 | J43: 340
A44: MEAN | B44: =AVERAGEA(B12:B41) -> 86.5 | C44: =AVERAGEA(C12:C41) -> 63.933333 | D44: =(B44+C44)/2 -> 75.216667 | E44: =IF(65-D44>0,65-M44,0) -> 0 | F44: =IF((D44)-65<0,0,(D44)-65) -> 10.216667 | G44: =AVERAGEA(G12:G41) -> 0.038666667 | H44: =AVERAGEA(H12:H41) -> 0 | I44: =AVERAGEA(I12:I41) -> 23.866667 | J44: =AVERAGEA(J12:J41) -> 164.66667
A45: CLIMO. | B45: 108 | C45: 31 | D45: =AVERAGEA(B45:C45) -> 69.5 | E45: =AVERAGEA(E13:E41) -> 0.72413793 | F45: =AVERAGEA(F13:F41) -> 10.862069 | G45: 2.2 | H45: N/A | I45: 10 | J45: 150
A46: PRECIPITATION ABOVE CLIMO. SNOWFALL DATA "T" = HAIL | G46: =(G42-G45) -> -1.04
A47: NOTE: CLIMO. TEMPERATURES ARE EXTREMES.
B51: TEMPERATURE | G51: PRECIP. | J51: WIND
B52: EXTRME MAX | C52: MEAN MAX | D52: MEAN | E52: MEAN MIN | F52: EXTRME MIN | G52: MAX | H52: MEAN | I52: 24 HR MAX | J52: MAX
A53: FROM ABOVE | B53: =MAXA(B11:B41) -> 94 | C53: =AVERAGEA(B11:B41) -> 86.5 | D53: =(B44+C44)/2 -> 75.216667 | E53: =AVERAGEA(C11:C41) -> 63.933333 | F53: =MINA(C11:C41) -> 40 | G53: =SUM(G11:G41) -> 1.16 | H53: =AVERAGEA(G11:G41) -> 0.038666667 | I53: =MAXA(G11:G39) -> 0.8 | J53: =MAXA(I11:I39) -> 33
A54: CLIMO | B54: 108 | C54: 82 | D54: 70 | E54: 60 | F54: 31 | G54: 10.2 | H54: 2.2 | I54: 3.4 | J54: 57

Sheet May
A1: 502 OSS/OSW LACKLAND AFB, KELLY ANNEX
A2: DAILY CLIMATOLOGICAL DATA
A3: FOR
A4: MAY 2025
B6: TEMPERATURE | G6: PRECIPITATION | I6: WIND
D7: DEGREE DAYS | G7: WATER | H7: DAILY
D8: BASE = 65 | G8: EQUIV- | H8: SNOW | I8: MAX | J8: DIREC-
A9: DAY | B9: MAX | C9: MIN | D9: MEAN | E9: HEATING | F9: COOLING | G9: ALENT | H9: FALL | I9: SPEED | J9: TION
A11: 1 | B11: 91 | C11: 74 | D11: =(B11+C11)/2 -> 82.5 | E11: =IF(65-D11>0,65-M11,0) -> 0 | F11: =IF((D11)-65<0,0,(D11)-65) -> 17.5 | G11: 0.05 | H11: 0 | I11: 36 | J11: 150 | M11: =IF(D11=0,65,D11) -> 82.5
A12: 2 | B12: 88 | C12: 67 | D12: =(B12+C12)/2 -> 77.5 | E12: =IF(65-D12>0,65-M12,0) -> 0 | F12: =IF((D12)-65<0,0,(D12)-65) -> 12.5 | G12: 0 | H12: 0 | I12: 28 | J12: 10 | M12: =IF(D12=0,65,D12) -> 77.5
A13: 3 | B13: 84 | C13: 64 | D13: =(B13+C13)/2 -> 74 | E13: =IF(65-D13>0,65-M13,0) -> 0 | F13: =IF((D13)-65<0,0,(D13)-65) -> 9 | G13: 0 | H13: 0 | I13: 24 | J13: 20 | M13: =IF(D13=0,65,D13) -> 74
A14: 4 | B14: 86 | C14: 59 | D14: =(B14+C14)/2 -> 72.5 | E14: =IF(65-D14>0,65-M14,0) -> 0 | F14: =IF((D14)-65<0,0,(D14)-65) -> 7.5 | G14: 0 | H14: 0 | I14: 19 | J14: 100 | M14: =IF(D14=0,65,D14) -> 72.5
A15: 5 | B15: 84 | C15: 70 | D15: =(B15+C15)/2 -> 77 | E15: =IF(65-D15>0,65-M15,0) -> 0 | F15: =IF((D15)-65<0,0,(D15)-65) -> 12 | G15: 0 | H15: 0 | I15: 21 | J15: 90 | M15: =IF(D15=0,65,D15) -> 77
A16: 6 | B16: 92 | C16: 69 | D16: =(B16+C16)/2 -> 80.5 | E16: =IF(65-D16>0,65-M16,0) -> 0 | F16: =IF((D16)-65<0,0,(D16)-65) -> 15.5 | G16: 0 | H16: 0 | I16: 16 | J16: 130 | M16: =IF(D16=0,65,D16) -> 80.5
A17: 7 | B17: 89 | C17: 67 | D17: =(B17+C17)/2 -> 78 | E17: =IF(65-D17>0,65-M17,0) -> 0 | F17: =IF((D17)-65<0,0,(D17)-65) -> 13 | G17: 0 | H17: 0 | I17: 20 | J17: 70 | M17: =IF(D17=0,65,D17) -> 78
A18: 8 | B18: 88 | C18: 66 | D18: =(B18+C18)/2 -> 77 | E18: =IF(65-D18>0,65-M18,0) -> 0 | F18: =IF((D18)-65<0,0,(D18)-65) -> 12 | G18: 0.02 | H18: 0 | I18: 27 | J18: 40 | M18: =IF(D18=0,65,D18) -> 77
A19: 9 | B19: 88 | C19: 63 | D19: =(B19+C19)/2 -> 75.5 | E19: =IF(65-D19>0,65-M19,0) -> 0 | F19: =IF((D19)-65<0,0,(D19)-65) -> 10.5 | G19: 0 | H19: 0 | I19: 26 | J19: 30 | M19: =IF(D19=0,65,D19) -> 75.5
A20: 10 | B20: 86 | C20: 63 | D20: =(B20+C20)/2 -> 74.5 | E20: =IF(65-D20>0,65-M20,0) -> 0 | F20: =IF((D20)-65<0,0,(D20)-65) -> 9.5 | G20: 0 | H20: 0 | I20: 34 | J20: 340 | M20: =IF(D20=0,65,D20) -> 74.5
A21: 11 | B21: 89 | C21: 60 | D21: =(B21+C21)/2 -> 74.5 | E21: =IF(65-D21>0,65-M21,0) -> 0 | F21: =IF((D21)-65<0,0,(D21)-65) -> 9.5 | G21: 0 | H21: 0 | I21: 22 | J21: 360 | M21: =IF(D21=0,65,D21) -> 74.5
A22: 12 | B22: 95 | C22: 53 | D22: =(B22+C22)/2 -> 74 | E22: =IF(65-D22>0,65-M22,0) -> 0 | F22: =IF((D22)-65<0,0,(D22)-65) -> 9 | G22: 0 | H22: 0 | I22: 13 | J22: 230 | M22: =IF(D22=0,65,D22) -> 74
... A41: 31 | B41: 88 | C41: 71 | D41: =(B41+C41)/2 -> 79.5 | E41: =IF(65-D41>0,65-M41,0) -> 0 | F41: =IF((D41)-65<0,0,(D41)-65) -> 14.5 | G41: 0 | H41: 0 | I41: 13 | J41: 220 | M41: =IF(D41=0,65,D41) -> 79.5
A42: TOTAL | B42: N/A | C42: N/A | D42: =SUM(D11:D41) -> 2535 | E42: =SUM(E11:E41) -> 0 | F42: =SUM(F11:F41) -> 520 | G42: =SUM(G11:G41) -> 2.12 | H42: =SUM(H11:H41) -> 0 | I42: N/A | J42: N/A | M42: =IF(D42=0,65,D42) -> 2535
A43: EXTREME | B43: =MAXA(B11:B41) -> 104 | C43: =MINA(C11:C41) -> 53 | D43: =(B43+C43)/2 -> 78.5 | E43: =IF(65-D43>0,65-M43,0) -> 0 | F43: =IF((D43)-65<0,0,(D43)-65) -> 13.5 | G43: =MAXA(G11:G41) -> 1.58 | H43: =MAXA(H12:H41) -> 0 | I43: =MAXA(I11:I41) -> 36 | J43: 150
A44: MEAN | B44: =AVERAGEA(B11:B41) -> 93.451613 | C44: =AVERAGEA(C11:C41) -> 70.096774 | D44: =(B44+C44)/2 -> 81.774194 | E44: =IF(65-D44>0,65-M44,0) -> 0 | F44: =IF((D44)-65<0,0,(D44)-65) -> 16.774194 | G44: =AVERAGEA(G11:G41) -> 0.068387097 | H44: =AVERAGEA(H11:H41) -> 0 | I44: =AVERAGEA(I11:I41) -> 24.129032 | J44: =AVERAGEA(J11:J41) -> 136.45161
A45: CLIMO. | B45: 104 | C45: 41 | D45: 76 | E45: =AVERAGEA(E12:E41) -> 0 | F45: =AVERAGEA(F12:F41) -> 16.75 | G45: 3.7 | H45: N/A | I45: 10 | J45: 150
A46: PRECIPITATION ABOVE CLIMO. | G46: =(G42-G45) -> -1.58
A47: NOTE: CLIMO. TEMPERATURES ARE EXTREMES. T = TRACE
B51: TEMPERATURE | G51: PRECIP. | J51: WIND
B52: EXTRME MAX | C52: MEAN MAX | D52: MEAN | E52: MEAN MIN | F52: EXTRME MIN | G52: MAX | H52: MEAN | I52: 24 HR MAX | J52: MAX
A53: FROM ABOVE | B53: =MAXA(B11:B41) -> 104 | C53: =AVERAGEA(B11:B41) -> 93.451613 | D53: =(B44+C44)/2 -> 81.774194 | E53: =AVERAGEA(C11:C41) -> 70.096774 | F53: =MINA(C11:C41) -> 53 | G53: =SUM(G11:G41) -> 2.12 | H53: =AVERAGEA(G11:G41) -> 0.068387097 | I53: =MAXA(G11:G39) -> 0.47 | J53: =MAXA(I11:I39) -> 36
A54: CLIMO | B54: 104 | C54: 88 | D54: 76 | E54: 68 | F54: 41 | G54: 11.2 | H54: 3.7 | I54: 8.4 | J54: 106

Sheet Jun 
A2: 502 OSS/OSW LACKLAND AFB, KELLY ANNEX, TX
A3: DAILY CLIMATOLOGICAL DATA
A4: FOR
A5: JUNE 2025
B7: TEMPERATURE | G7: PRECIPITATION | I7: WIND
D8: DEGREE DAYS | G8: WATER | H8: DAILY
D9: BASE = 65 | G9: EQUIV- | H9: SNOW | I9: MAX | J9: DIREC-
A10: DAY | B10: MAX | C10: MIN | D10: MEAN | E10: HEATING | F10: COOLING | G10: ALENT | H10: FALL | I10: SPEED | J10: TION
A12: 1 | B12: 96 | C12: 73 | D12: =(B12+C12)/2 -> 84.5 | E12: =IF(65-D12>0,65-M12,0) -> 0 | F12: =IF((D12)-65<0,0,(D12)-65) -> 19.5 | G12: 0 | H12: 0 | I12: 23 | J12: 140 | M12: =IF(D12=0,65,D12) -> 84.5
A13: 2 | B13: 94 | C13: 73 | D13: =(B13+C13)/2 -> 83.5 | E13: =IF(65-D13>0,65-M13,0) -> 0 | F13: =IF((D13)-65<0,0,(D13)-65) -> 18.5 | G13: 0 | H13: 0 | I13: 20 | J13: 100 | M13: =IF(D13=0,65,D13) -> 83.5
A14: 3 | B14: 93 | C14: 78 | D14: =(B14+C14)/2 -> 85.5 | E14: =IF(65-D14>0,65-M14,0) -> 0 | F14: =IF((D14)-65<0,0,(D14)-65) -> 20.5 | G14: 0 | H14: 0 | I14: 21 | J14: 150 | M14: =IF(D14=0,65,D14) -> 85.5
A15: 4 | B15: 95 | C15: 79 | D15: =(B15+C15)/2 -> 87 | E15: =IF(65-D15>0,65-M15,0) -> 0 | F15: =IF((D15)-65<0,0,(D15)-65) -> 22 | G15: 0 | H15: 0 | I15: 21 | J15: 130 | M15: =IF(D15=0,65,D15) -> 87
A16: 5 | B16: 96 | C16: 78 | D16: =(B16+C16)/2 -> 87 | E16: =IF(65-D16>0,65-M16,0) -> 0 | F16: =IF((D16)-65<0,0,(D16)-65) -> 22 | G16: 0 | H16: 0 | I16: 23 | J16: 130 | M16: =IF(D16=0,65,D16) -> 87
A17: 6 | B17: 97 | C17: 77 | D17: =(B17+C17)/2 -> 87 | E17: =IF(65-D17>0,65-M17,0) -> 0 | F17: =IF((D17)-65<0,0,(D17)-65) -> 22 | G17: 0 | H17: 0 | I17: 25 | J17: 130 | M17: =IF(D17=0,65,D17) -> 87
A18: 7 | B18: 98 | C18: 78 | D18: =(B18+C18)/2 -> 88 | E18: =IF(65-D18>0,65-M18,0) -> 0 | F18: =IF((D18)-65<0,0,(D18)-65) -> 23 | G18: 0 | H18: 0 | I18: 20 | J18: 120 | M18: =IF(D18=0,65,D18) -> 88
A19: 8 | B19: 99 | C19: 78 | D19: =(B19+C19)/2 -> 88.5 | E19: =IF(65-D19>0,65-M19,0) -> 0 | F19: =IF((D19)-65<0,0,(D19)-65) -> 23.5 | G19: 0 | H19: 0 | I19: 24 | J19: 140 | M19: =IF(D19=0,65,D19) -> 88.5
A20: 9 | B20: 99 | C20: 78 | D20: =(B20+C20)/2 -> 88.5 | E20: =IF(65-D20>0,65-M20,0) -> 0 | F20: =IF((D20)-65<0,0,(D20)-65) -> 23.5 | G20: 0 | H20: 0 | I20: 20 | J20: 140 | M20: =IF(D20=0,65,D20) -> 88.5
A21: 10 | B21: 96 | C21: 76 | D21: =(B21+C21)/2 -> 86 | E21: =IF(65-D21>0,65-M21,0) -> 0 | F21: =IF((D21)-65<0,0,(D21)-65) -> 21 | G21: 0 | H21: 0 | I21: 36 | J21: 240 | M21: =IF(D21=0,65,D21) -> 86
A22: 11 | B22: 88 | C22: 70 | D22: =(B22+C22)/2 -> 79 | E22: =IF(65-D22>0,65-M22,0) -> 0 | F22: =IF((D22)-65<0,0,(D22)-65) -> 14 | G22: 0.43 | H22: 0 | I22: 41 | J22: 160 | M22: =IF(D22=0,65,D22) -> 79
A23: 12 | B23: 81 | C23: 70 | D23: =(B23+C23)/2 -> 75.5 | E23: =IF(65-D23>0,65-M23,0) -> 0 | F23: =IF((D23)-65<0,0,(D23)-65) -> 10.5 | G23: 1.86 | H23: 0 | I23: 22 | J23: 20 | M23: =IF(D23=0,65,D23) -> 75.5
... A41: 30 | B41: 94 | C41: 74 | D41: =(B41+C41)/2 -> 84 | E41: =IF(65-D41>0,65-M41,0) -> 0 | F41: =IF((D41)-65<0,0,(D41)-65) -> 19 | G41: 0.07 | H41: 0 | I41: 34 | J41: 170 | M41: =IF(D41=0,65,D41) -> 84
A42: TOTAL | B42: N/A | C42: N/A | D42: =SUM(D12:D41) -> 2554.5 | E42: =SUM(E12:E41) -> 0 | F42: =SUM(F12:F41) -> 604.5 | G42: =SUM(G12:G41) -> 3.05 | H42: =SUM(H12:H41) -> 0 | I42: N/A | J42: N/A | M42: =IF(D42=0,65,D42) -> 2554.5
A43: EXTREME | B43: =MAXA(B12:B41) -> 99 | C43: =MINA(C12:C41) -> 70 | D43: =(B43+C43)/2 -> 84.5 | E43: =IF(65-D43>0,65-M43,0) -> 0 | F43: =IF((D43)-65<0,0,(D43)-65) -> 19.5 | G43: =MAXA(G13:G41) -> 1.86 | H43: =MAXA(H13:H41) -> 0 | I43: =MAXA(I12:I41) -> 41 | J43: 160
A44: MEAN | B44: =AVERAGEA(B12:B41) -> 94.766667 | C44: =AVERAGEA(C12:C41) -> 75.533333 | D44: =(B44+C44)/2 -> 85.15 | E44: =IF(65-D44>0,65-M44,0) -> 0 | F44: =IF((D44)-65<0,0,(D44)-65) -> 20.15 | G44: =AVERAGEA(G12:G41) -> 0.10166667 | H44: =AVERAGEA(H12:H41) -> 0 | I44: =AVERAGEA(I12:I41) -> 25.366667 | J44: =AVERAGEA(J12:J41) -> 145
A45: CLIMO. | B45: 109 | C45: 55 | D45: 82 | E45: =AVERAGEA(E13:E41) -> 0 | F45: =AVERAGEA(F13:F41) -> 20.172414 | G45: 3 | H45: N/A | I45: 8 | J45: 160
A46: PRECIPITATION ABOVE CLIMO. | G46: =(G42-G45) -> 0.05
A47: NOTE: CLIMO. TEMPERATURES ARE EXTREMES.
B51: TEMPERATURE | G51: PRECIP. | J51: WIND
B52: EXTRME MAX | C52: MEAN MAX | D52: MEAN | E52: MEAN MIN | F52: EXTRME MIN | G52: MAX | H52: MEAN | I52: 24 HR MAX | J52: MAX
A53: FROM ABOVE | B53: =MAXA(B11:B41) -> 99 | C53: =AVERAGEA(B11:B41) -> 94.766667 | D53: =(B44+C44)/2 -> 85.15 | E53: =AVERAGEA(C11:C41) -> 75.533333 | F53: =MINA(C11:C41) -> 70 | G53: =SUM(G11:G41) -> 3.05 | H53: =AVERAGEA(G11:G41) -> 0.10166667 | I53: =MAXA(G11:G39) -> 1.86 | J53: =MAXA(I11:I39) -> 41
A54: CLIMO | B54: 109 | C54: 93 | D54: 82 | E54: 73 | F54: 55 | G54: 13.5 | H54: 3 | I54: 4.7 | J54: 75

Sheet Jul 
A2: 502 OSS/OSW LACKLAND AFB, KELLY ANNEX, TX
A3: DAILY CLIMATOLOGICAL DATA
A4: FOR
A5: JULY 2025
B7: TEMPERATURE | G7: PRECIPITATION | I7: WIND
D8: DEGREE DAYS | G8: WATER | H8: DAILY
D9: BASE = 65 | G9: EQUIV- | H9: SNOW | I9: MAX | J9: DIREC-
A10: DAY | B10: MAX | C10: MIN | D10: MEAN | E10: HEATING | F10: COOLING | G10: ALENT | H10: FALL | I10: SPEED | J10: TION
A12: 1 | B12: 93 | C12: 74 | D12: =(B12+C12)/2 -> 83.5 | E12: =IF(65-D12>0,65-M12,0) -> 0 | F12: =IF((D12)-65<0,0,(D12)-65) -> 18.5 | G12: 0 | H12: 0 | I12: 22 | J12: 150 | M12: =IF(D12=0,65,D12) -> 83.5
A13: 2 | B13: 91 | C13: 76 | D13: =(B13+C13)/2 -> 83.5 | E13: =IF(65-D13>0,65-M13,0) -> 0 | F13: =IF((D13)-65<0,0,(D13)-65) -> 18.5 | G13: 0.1 | H13: 0 | I13: 30 | J13: 130 | M13: =IF(D13=0,65,D13) -> 83.5
A14: 3 | B14: 93 | C14: 77 | D14: =(B14+C14)/2 -> 85 | E14: =IF(65-D14>0,65-M14,0) -> 0 | F14: =IF((D14)-65<0,0,(D14)-65) -> 20 | G14: 0.14 | H14: 0 | I14: 26 | J14: 130 | M14: =IF(D14=0,65,D14) -> 85
A15: 4 | B15: 84 | C15: 77 | D15: =(B15+C15)/2 -> 80.5 | E15: =IF(65-D15>0,65-M15,0) -> 0 | F15: =IF((D15)-65<0,0,(D15)-65) -> 15.5 | G15: 0.13 | H15: 0 | I15: 16 | J15: 130 | M15: =IF(D15=0,65,D15) -> 80.5
A16: 5 | B16: 82 | C16: 78 | D16: =(B16+C16)/2 -> 80 | E16: =IF(65-D16>0,65-M16,0) -> 0 | F16: =IF((D16)-65<0,0,(D16)-65) -> 15 | G16: 0.01 | H16: 0 | I16: 15 | J16: 170 | M16: =IF(D16=0,65,D16) -> 80
A17: 6 | B17: 79 | C17: 75 | D17: =(B17+C17)/2 -> 77 | E17: =IF(65-D17>0,65-M17,0) -> 0 | F17: =IF((D17)-65<0,0,(D17)-65) -> 12 | G17: 0.17 | H17: 0 | I17: 22 | J17: 140 | M17: =IF(D17=0,65,D17) -> 77
A18: 7 | B18: 95 | C18: 78 | D18: =(B18+C18)/2 -> 86.5 | E18: =IF(65-D18>0,65-M18,0) -> 0 | F18: =IF((D18)-65<0,0,(D18)-65) -> 21.5 | G18: 0 | H18: 0 | I18: 23 | J18: 130 | M18: =IF(D18=0,65,D18) -> 86.5
A19: 8 | B19: 94 | C19: 75 | D19: =(B19+C19)/2 -> 84.5 | E19: =IF(65-D19>0,65-M19,0) -> 0 | F19: =IF((D19)-65<0,0,(D19)-65) -> 19.5 | G19: 0 | H19: 0 | I19: 28 | J19: 150 | M19: =IF(D19=0,65,D19) -> 84.5
A20: 9 | B20: 94 | C20: 76 | D20: =(B20+C20)/2 -> 85 | E20: =IF(65-D20>0,65-M20,0) -> 0 | F20: =IF((D20)-65<0,0,(D20)-65) -> 20 | G20: 0 | H20: 0 | I20: 20 | J20: 130 | M20: =IF(D20=0,65,D20) -> 85
A21: 10 | B21: 98 | C21: 72 | D21: =(B21+C21)/2 -> 85 | E21: =IF(65-D21>0,65-M21,0) -> 0 | F21: =IF((D21)-65<0,0,(D21)-65) -> 20 | G21: 0 | H21: 0 | I21: 22 | J21: 150 | M21: =IF(D21=0,65,D21) -> 85
A22: 11 | B22: 95 | C22: 77 | D22: =(B22+C22)/2 -> 86 | E22: =IF(65-D22>0,65-M22,0) -> 0 | F22: =IF((D22)-65<0,0,(D22)-65) -> 21 | G22: 0 | H22: 0 | I22: 24 | J22: 140 | M22: =IF(D22=0,65,D22) -> 86
A23: 12 | B23: 97 | C23: 78 | D23: =(B23+C23)/2 -> 87.5 | E23: =IF(65-D23>0,65-M23,0) -> 0 | F23: =IF((D23)-65<0,0,(D23)-65) -> 22.5 | G23: 0 | H23: 0 | I23: 25 | J23: 130 | M23: =IF(D23=0,65,D23) -> 87.5
... A42: 31 | B42: 104 | C42: 73 | D42: =(B42+C42)/2 -> 88.5 | E42: =IF(65-D42>0,65-M42,0) -> 0 | F42: =IF((D42)-65<0,0,(D42)-65) -> 23.5 | G42: 0 | H42: 0 | I42: 17 | J42: 140 | M42: =IF(D42=0,65,D42) -> 88.5
A43: TOTAL | B43: N/A | C43: N/A | D43: =SUM(D12:D42) -> 2673 | E43: =SUM(E12:E42) -> 0 | F43: =SUM(F12:F42) -> 658 | G43: =SUM(G12:G42) -> 0.66 | H43: =SUM(H12:H42) -> 0 | I43: N/A | J43: N/A | M43: =IF(D43=0,65,D43) -> 2673
A44: EXTREME | B44: =MAXA(B12:B42) -> 104 | C44: =MINA(C12:C42) -> 66 | D44: =(B44+C44)/2 -> 85 | E44: =IF(65-D44>0,65-M44,0) -> 0 | F44: =IF((D44)-65<0,0,(D44)-65) -> 20 | G44: =MAXA(G12:G42) -> 0.17 | H44: =MAXA(H13:H42) -> 0 | I44: =MAXA(I12:I42) -> 30 | J44: 130
A45: MEAN | B45: =AVERAGEA(B12:B42) -> 96.032258 | C45: =AVERAGEA(C12:C42) -> 76.419355 | D45: =(B45+C45)/2 -> 86.225806 | E45: =IF(65-D45>0,65-M45,0) -> 0 | F45: =IF((D45)-65<0,0,(D45)-65) -> 21.225806 | G45: =AVERAGEA(G12:G42) -> 0.021290323 | H45: =AVERAGEA(H12:H42) -> 0 | I45: =AVERAGEA(I12:I42) -> 22.032258 | J45: =AVERAGE(J12:J42) -> 148.06452
A46: CLIMO. | B46: 108 | C46: 61 | D46: 85 | E46: =AVERAGEA(E13:E42) -> 0 | F46: =AVERAGEA(F13:F42) -> 21.316667 | G46: 1.9 | H46: N/A | I46: 8 | J46: 160
A47: PRECIPITATION ABOVE CLIMO. | G47: =(G43-G46) -> -1.24
B54: TEMPERATURE | G54: PRECIP. | J54: WIND
B55: EXTRME MAX | C55: MEAN MAX | D55: MEAN | E55: MEAN MIN | F55: EXTRME MIN | G55: MAX | H55: MEAN | I55: 24 HR MAX | J55: MAX
A56: FROM ABOVE | B56: =MAXA(B12:B42) -> 104 | C56: =AVERAGEA(B12:B42) -> 96.032258 | D56: =(B45+C45)/2 -> 86.225806 | E56: =AVERAGEA(C12:C42) -> 76.419355 | F56: =MINA(C12:C42) -> 66 | G56: =SUM(G12:G42) -> 0.66 | H56: =AVERAGEA(G12:G42) -> 0.021290323 | I56: =MAXA(G12:G42) -> 0.17 | J56: =MAXA(I12:I42) -> 30
A57: CLIMO | B57: 108 | C57: 97 | D57: 85 | E57: 75 | F57: 61 | G57: 12.3 | H57: 1.9 | I57: 6.8 | J57: 65

Sheet Aug
A2: 502 OSS/OSW LACKLAND AFB, KELLY ANNEX, TX
A3: DAILY CLIMATOLOGICAL DATA
A4: FOR
A5: AUGUST 2025
B7: TEMPERATURE | G7: PRECIPITATION | I7: WIND
D8: DEGREE DAYS | G8: WATER | H8: DAILY
D9: BASE = 65 | G9: EQUIV- | H9: SNOW | I9: MAX | J9: DIREC-
A10: DAY | B10: MAX | C10: MIN | D10: MEAN | E10: HEATING | F10: COOLING | G10: ALENT | H10: FALL | I10: SPEED | J10: TION
A12: 1 | B12: 103 | C12: 77 | D12: =(B12+C12)/2 -> 90 | E12: =IF(65-D12>0,65-M12,0) -> 0 | F12: =IF((D12)-65<0,0,(D12)-65) -> 25 | G12: 0 | H12: 0 | I12: 17 | J12: 120 | M12: =IF(D12=0,65,D12) -> 90
A13: 2 | B13: 105 | C13: 77 | D13: =(B13+C13)/2 -> 91 | E13: =IF(65-D13>0,65-M13,0) -> 0 | F13: =IF((D13)-65<0,0,(D13)-65) -> 26 | G13: 0.29 | H13: 0 | I13: 37 | J13: 320 | M13: =IF(D13=0,65,D13) -> 91
A14: 3 | B14: 101 | C14: 74 | D14: =(B14+C14)/2 -> 87.5 | E14: =IF(65-D14>0,65-M14,0) -> 0 | F14: =IF((D14)-65<0,0,(D14)-65) -> 22.5 | G14: 0 | H14: 0 | I14: 19 | J14: 140 | M14: =IF(D14=0,65,D14) -> 87.5
A15: 4 | B15: 95 | C15: 78 | D15: =(B15+C15)/2 -> 86.5 | E15: =IF(65-D15>0,65-M15,0) -> 0 | F15: =IF((D15)-65<0,0,(D15)-65) -> 21.5 | G15: 0 | H15: 0 | I15: 22 | J15: 90 | M15: =IF(D15=0,65,D15) -> 86.5
A16: 5 | B16: 100 | C16: 72 | D16: =(B16+C16)/2 -> 86 | E16: =IF(65-D16>0,65-M16,0) -> 0 | F16: =IF((D16)-65<0,0,(D16)-65) -> 21 | G16: 0 | H16: 0 | I16: 16 | J16: 70 | M16: =IF(D16=0,65,D16) -> 86
A17: 6 | B17: 101 | C17: 78 | D17: =(B17+C17)/2 -> 89.5 | E17: =IF(65-D17>0,65-M17,0) -> 0 | F17: =IF((D17)-65<0,0,(D17)-65) -> 24.5 | G17: 0 | H17: 0 | I17: 24 | J17: 120 | M17: =IF(D17=0,65,D17) -> 89.5
A18: 7 | B18: 100 | C18: 79 | D18: =(B18+C18)/2 -> 89.5 | E18: =IF(65-D18>0,65-M18,0) -> 0 | F18: =IF((D18)-65<0,0,(D18)-65) -> 24.5 | G18: 0 | H18: 0 | I18: 19 | J18: 150 | M18: =IF(D18=0,65,D18) -> 89.5
A19: 8 | B19: 102 | C19: 76 | D19: =(B19+C19)/2 -> 89 | E19: =IF(65-D19>0,65-M19,0) -> 0 | F19: =IF((D19)-65<0,0,(D19)-65) -> 24 | G19: 0 | H19: 0 | I19: 20 | J19: 140 | M19: =IF(D19=0,65,D19) -> 89
A20: 9 | B20: 102 | C20: 77 | D20: =(B20+C20)/2 -> 89.5 | E20: =IF(65-D20>0,65-M20,0) -> 0 | F20: =IF((D20)-65<0,0,(D20)-65) -> 24.5 | G20: 0 | H20: 0 | I20: 20 | J20: 130 | M20: =IF(D20=0,65,D20) -> 89.5
A21: 10 | B21: 101 | C21: 77 | D21: =(B21+C21)/2 -> 89 | E21: =IF(65-D21>0,65-M21,0) -> 0 | F21: =IF((D21)-65<0,0,(D21)-65) -> 24 | G21: 0 | H21: 0 | I21: 23 | J21: 130 | M21: =IF(D21=0,65,D21) -> 89
A22: 11 | B22: 101 | C22: 78 | D22: =(B22+C22)/2 -> 89.5 | E22: =IF(65-D22>0,65-M22,0) -> 0 | F22: =IF((D22)-65<0,0,(D22)-65) -> 24.5 | G22: 0 | H22: 0 | I22: 22 | J22: 130 | M22: =IF(D22=0,65,D22) -> 89.5
A23: 12 | B23: 102 | C23: 77 | D23: =(B23+C23)/2 -> 89.5 | E23: =IF(65-D23>0,65-M23,0) -> 0 | F23: =IF((D23)-65<0,0,(D23)-65) -> 24.5 | G23: 0 | H23: 0 | I23: 19 | J23: 30 | M23: =IF(D23=0,65,D23) -> 89.5
... A42: 31 | B42: 100 | C42: 74 | D42: =(B42+C42)/2 -> 87 | E42: =IF(65-D42>0,65-M42,0) -> 0 | F42: =IF((D42)-65<0,0,(D42)-65) -> 22 | G42: 1.55 | H42: 0 | I42: 36 | J42: 10 | M42: =IF(D42=0,65,D42) -> 87
A43: TOTAL | B43: N/A | C43: N/A | D43: =SUM(D12:D42) -> 2748.5 | E43: =SUM(E12:E42) -> 0 | F43: =SUM(F12:F42) -> 733.5 | G43: =SUM(G12:G42) -> 2.53 | H43: =SUM(H12:H42) -> 0 | I43: N/A | J43: N/A | M43: =IF(D43=0,65,D43) -> 2748.5
A44: EXTREME | B44: =MAXA(B12:B42) -> 105 | C44: =MINA(C12:C42) -> 72 | D44: =(B44+C44)/2 -> 88.5 | E44: =IF(65-D44>0,65-M44,0) -> 0 | F44: =IF((D44)-65<0,0,(D44)-65) -> 23.5 | G44: =MAXA(G13:G42) -> 1.55 | H44: =MAXA(H13:H42) -> 0 | I44: =MAXA(I12:I42) -> 37 | J44: 320
A45: MEAN | B45: =AVERAGEA(B12:B42) -> 100.6129 | C45: =AVERAGEA(C12:C42) -> 76.709677 | D45: =(B45+C45)/2 -> 88.66129 | E45: =IF(65-D45>0,65-M45,0) -> 0 | F45: =IF((D45)-65<0,0,(D45)-65) -> 23.66129 | G45: =AVERAGEA(G12:G42) -> 0.081612903 | H45: =AVERAGEA(H12:H42) -> 0 | I45: =AVERAGEA(I12:I42) -> 23 | J45: =AVERAGE(J12:J42) -> 133.54839
A46: CLIMO. | B46: 109 | C46: 59 | D46: 85 | E46: =AVERAGEA(E13:E42) -> 0 | F46: =AVERAGEA(F13:F42) -> 23.616667 | G46: 2.3 | H46: N/A | I46: 7 | J46: 160
A47: PRECIPITATION ABOVE CLIMO. | G47: =(G43-G46) -> 0.23
A48: NOTE: CLIMO. TEMPERATURES ARE EXTREMES.
B53: TEMPERATURE | G53: PRECIP. | J53: WIND
B54: EXTRME MAX | C54: MEAN MAX | D54: MEAN | E54: MEAN MIN | F54: EXTRME MIN | G54: MAX | H54: MEAN | I54: 24 HR MAX | J54: MAX
A55: FROM ABOVE | B55: =MAXA(B12:B42) -> 105 | C55: =AVERAGEA(B12:B42) -> 100.6129 | D55: =(B45+C45)/2 -> 88.66129 | E55: =AVERAGEA(C12:C42) -> 76.709677 | F55: =MINA(C12:C42) -> 72 | G55: =SUM(G12:G42) -> 2.53 | H55: =AVERAGEA(G12:G42) -> 0.081612903 | I55: =MAXA(G12:G42) -> 1.55 | J55: =MAXA(I12:I42) -> 37
A56: CLIMO | B56: 109 | C56: 97 | D56: 85 | E56: 76 | F56: 59 | G56: 15.1 | H56: 2.3 | I56: 7.2 | J56: 70

Sheet Sep
A2: 502 OSS/OSW LACKLAND AFB, KELLY ANNEX, TX
A3: DAILY CLIMATOLOGICAL DATA
A4: FOR
A5: SEPTEMBER 2025
B7: TEMPERATURE | D7: DEGREE DAYS | G7: PRECIPITATION | I7: WIND
D8: BASE = 65 | G8: WATER | H8: DAILY
G9: EQUIV- | H9: SNOW | I9: MAX | J9: DIREC-
A10: DAY | B10: MAX | C10: MIN | D10: MEAN | E10: HEATING | F10: COOLING | G10: ALENT | H10: FALL | I10: SPEED | J10: TION
A12: 1 | B12: 89 | C12: 76 | D12: =(B12+C12)/2 -> 82.5 | E12: =IF(65-D12>0,65-M12,0) -> 0 | F12: =IF((D12)-65<0,0,(D12)-65) -> 17.5 | G12: 0.01 | H12: 0 | I12: 14 | J12: 290 | M12: =IF(D12=0,65,D12) -> 82.5
A13: 2 | B13: 99 | C13: 73 | D13: =(B13+C13)/2 -> 86 | E13: =IF(65-D13>0,65-M13,0) -> 0 | F13: =IF((D13)-65<0,0,(D13)-65) -> 21 | G13: 0 | H13: 0 | I13: 22 | J13: 30 | M13: =IF(D13=0,65,D13) -> 86
A14: 3 | B14: 100 | C14: 76 | D14: =(B14+C14)/2 -> 88 | E14: =IF(65-D14>0,65-M14,0) -> 0 | F14: =IF((D14)-65<0,0,(D14)-65) -> 23 | G14: 0 | H14: 0 | I14: 18 | J14: 10 | M14: =IF(D14=0,65,D14) -> 88
A15: 4 | B15: 102 | C15: 69 | D15: =(B15+C15)/2 -> 85.5 | E15: =IF(65-D15>0,65-M15,0) -> 0 | F15: =IF((D15)-65<0,0,(D15)-65) -> 20.5 | G15: 0 | H15: 0 | I15: 20 | J15: 130 | M15: =IF(D15=0,65,D15) -> 85.5
A16: 5 | B16: 100 | C16: 77 | D16: =(B16+C16)/2 -> 88.5 | E16: =IF(65-D16>0,65-M16,0) -> 0 | F16: =IF((D16)-65<0,0,(D16)-65) -> 23.5 | G16: 0 | H16: 0 | I16: 25 | J16: 150 | M16: =IF(D16=0,65,D16) -> 88.5
A17: 6 | B17: 93 | C17: 77 | D17: =(B17+C17)/2 -> 85 | E17: =IF(65-D17>0,65-M17,0) -> 0 | F17: =IF((D17)-65<0,0,(D17)-65) -> 20 | G17: 0 | H17: 0 | I17: 35 | J17: 350 | M17: =IF(D17=0,65,D17) -> 85
A18: 7 | B18: 80 | C18: 73 | D18: =(B18+C18)/2 -> 76.5 | E18: =IF(65-D18>0,65-M18,0) -> 0 | F18: =IF((D18)-65<0,0,(D18)-65) -> 11.5 | G18: 0.17 | H18: 0 | I18: 16 | J18: 50 | M18: =IF(D18=0,65,D18) -> 76.5
A19: 8 | B19: 89 | C19: 70 | D19: =(B19+C19)/2 -> 79.5 | E19: =IF(65-D19>0,65-M19,0) -> 0 | F19: =IF((D19)-65<0,0,(D19)-65) -> 14.5 | G19: 0 | H19: 0 | I19: 16 | J19: 50 | M19: =IF(D19=0,65,D19) -> 79.5
A20: 9 | B20: 93 | C20: 66 | D20: =(B20+C20)/2 -> 79.5 | E20: =IF(65-D20>0,65-M20,0) -> 0 | F20: =IF((D20)-65<0,0,(D20)-65) -> 14.5 | G20: 0 | H20: 0 | I20: 12 | J20: 80 | M20: =IF(D20=0,65,D20) -> 79.5
A21: 10 | B21: 95 | C21: 69 | D21: =(B21+C21)/2 -> 82 | E21: =IF(65-D21>0,65-M21,0) -> 0 | F21: =IF((D21)-65<0,0,(D21)-65) -> 17 | G21: 0 | H21: 0 | I21: 11 | J21: 60 | M21: =IF(D21=0,65,D21) -> 82
A22: 11 | B22: 96 | C22: 68 | D22: =(B22+C22)/2 -> 82 | E22: =IF(65-D22>0,65-M22,0) -> 0 | F22: =IF((D22)-65<0,0,(D22)-65) -> 17 | G22: 0 | H22: 0 | I22: 20 | J22: 120 | M22: =IF(D22=0,65,D22) -> 82
A23: 12 | B23: 97 | C23: 76 | D23: =(B23+C23)/2 -> 86.5 | E23: =IF(65-D23>0,65-M23,0) -> 0 | F23: =IF((D23)-65<0,0,(D23)-65) -> 21.5 | G23: 0 | H23: 0 | I23: 22 | J23: 110 | M23: =IF(D23=0,65,D23) -> 86.5
... A41: 30 | B41: 94 | C41: 67 | D41: =(B41+C41)/2 -> 80.5 | E41: =IF(65-D41>0,65-M41,0) -> 0 | F41: =IF((D41)-65<0,0,(D41)-65) -> 15.5 | G41: 0 | H41: 0 | I41: 12 | J41: 150 | M41: =IF(D41=0,65,D41) -> 80.5
A42: TOTAL | B42: N/A | C42: N/A | D42: =SUM(D12:D41) -> 2503.5 | E42: =SUM(E12:E41) -> 0 | F42: =SUM(F12:F41) -> 553.5 | G42: =SUM(G12:G41) -> 0.18 | H42: =SUM(H12:H41) -> 0 | I42: N/A | J42: N/A | M42: =IF(D42=0,65,D42) -> 2503.5
A43: EXTREME | B43: =MAXA(B12:B41) -> 102 | C43: =MINA(C12:C41) -> 65 | D43: =(B43+C43)/2 -> 83.5 | E43: =IF(65-D43>0,65-M43,0) -> 0 | F43: =IF((D43)-65<0,0,(D43)-65) -> 18.5 | G43: =MAXA(G13:G41) -> 0.17 | H43: =MAXA(H13:H41) -> 0 | I43: =MAXA(I12:I41) -> 35 | J43: 350
A44: MEAN | B44: =AVERAGEA(B12:B41) -> 94.833333 | C44: =AVERAGEA(C12:C41) -> 72.066667 | D44: =(B44+C44)/2 -> 83.45 | E44: =IF(65-D44>0,65-M44,0) -> 0 | F44: =IF((D44)-65<0,0,(D44)-65) -> 18.45 | G44: =AVERAGEA(G12:G41) -> 0.006 | H44: =AVERAGEA(H12:H41) -> 0 | I44: =AVERAGEA(I12:I41) -> 19.633333 | J44: =AVERAGE(J12:J41) -> 142
A45: CLIMO. | B45: 111 | C45: 41 | D45: 81 | E45: =AVERAGEA(E13:E41) -> 0 | F45: =AVERAGEA(F13:F41) -> 18.482759 | G45: 3.4 | H45: N/A | I45: 7 | J45: 160
A46: PRECIPITATION ABOVE CLIMO. | G46: =(G42-G45) -> -3.22
A47: NOTE: CLIMO. TEMPERATURES ARE EXTREMES.
B51: TEMPERATURE | G51: PRECIP. | J51: WIND
B52: EXTRME MAX | C52: MEAN MAX | D52: MEAN | E52: MEAN MIN | F52: EXTRME MIN | G52: MAX | H52: MEAN | I52: 24 HR MAX | J52: MAX
A53: FROM ABOVE | B53: =MAXA(B11:B41) -> 102 | C53: =AVERAGEA(B11:B41) -> 94.833333 | D53: =(B44+C44)/2 -> 83.45 | E53: =AVERAGEA(C11:C41) -> 72.066667 | F53: =MINA(C11:C41) -> 65 | G53: =SUM(G11:G41) -> 0.18 | H53: =AVERAGEA(G11:G41) -> 0.006 | I53: =MAXA(G11:G39) -> 0.17 | J53: =MAXA(I11:I39) -> 35
A54: CLIMO | B54: 111 | C54: 92 | D54: 81 | E54: 72 | F54: 41 | G54: 13.5 | H54: 3.4 | I54: 8.1 | J54: 55

Sheet Oct 
A2: 502 OSS/OSW LACKLAND AFB, KELLY ANNEX, TX
A3: DAILY CLIMATOLOGICAL DATA
A4: FOR
A5: OCTOBER 2025
B7: TEMPERATURE | G7: PRECIPITATION | I7: WIND
D8: DEGREE DAYS | G8: WATER | H8: DAILY
D9: BASE = 65 | G9: EQUIV- | H9: SNOW | I9: MAX | J9: DIREC-
A10: DAY | B10: MAX | C10: MIN | D10: MEAN | E10: HEATING | F10: COOLING | G10: ALENT | H10: FALL | I10: SPEED | J10: TION
A12: 1 | B12: 96 | C12: 66 | D12: =(B12+C12)/2 -> 81 | E12: =IF(65-D12>0,65-M12,0) -> 0 | F12: =IF((D12)-65<0,0,(D12)-65) -> 16 | G12: 0 | H12: 0 | I12: 12 | J12: 220 | M12: =IF(D12=0,65,D12) -> 81
A13: 2 | B13: 96 | C13: 66 | D13: =(B13+C13)/2 -> 81 | E13: =IF(65-D13>0,65-M13,0) -> 0 | F13: =IF((D13)-65<0,0,(D13)-65) -> 16 | G13: 0 | H13: 0 | I13: 10 | J13: 120 | M13: =IF(D13=0,65,D13) -> 81
A14: 3 | B14: 95 | C14: 69 | D14: =(B14+C14)/2 -> 82 | E14: =IF(65-D14>0,65-M14,0) -> 0 | F14: =IF((D14)-65<0,0,(D14)-65) -> 17 | G14: 0 | H14: 0 | I14: 13 | J14: 30 | M14: =IF(D14=0,65,D14) -> 82
A15: 4 | B15: 92 | C15: 70 | D15: =(B15+C15)/2 -> 81 | E15: =IF(65-D15>0,65-M15,0) -> 0 | F15: =IF((D15)-65<0,0,(D15)-65) -> 16 | G15: 0 | H15: 0 | I15: 20 | J15: 140 | M15: =IF(D15=0,65,D15) -> 81
A16: 5 | B16: 93 | C16: 69 | D16: =(B16+C16)/2 -> 81 | E16: =IF(65-D16>0,65-M16,0) -> 0 | F16: =IF((D16)-65<0,0,(D16)-65) -> 16 | G16: 0 | H16: 0 | I16: 15 | J16: 160 | M16: =IF(D16=0,65,D16) -> 81
A17: 6 | B17: 93 | C17: 72 | D17: =(B17+C17)/2 -> 82.5 | E17: =IF(65-D17>0,65-M17,0) -> 0 | F17: =IF((D17)-65<0,0,(D17)-65) -> 17.5 | G17: 0 | H17: 0 | I17: 19 | J17: 150 | M17: =IF(D17=0,65,D17) -> 82.5
A18: 7 | B18: 96 | C18: 76 | D18: =(B18+C18)/2 -> 86 | E18: =IF(65-D18>0,65-M18,0) -> 0 | F18: =IF((D18)-65<0,0,(D18)-65) -> 21 | G18: 0 | H18: 0 | I18: 22 | J18: 150 | M18: =IF(D18=0,65,D18) -> 86
A19: 8 | B19: 95 | C19: 74 | D19: =(B19+C19)/2 -> 84.5 | E19: =IF(65-D19>0,65-M19,0) -> 0 | F19: =IF((D19)-65<0,0,(D19)-65) -> 19.5 | G19: 0 | H19: 0 | I19: 18 | J19: 70 | M19: =IF(D19=0,65,D19) -> 84.5
A20: 9 | B20: 93 | C20: 76 | D20: =(B20+C20)/2 -> 84.5 | E20: =IF(65-D20>0,65-M20,0) -> 0 | F20: =IF((D20)-65<0,0,(D20)-65) -> 19.5 | G20: 0 | H20: 0 | I20: 21 | J20: 50 | M20: =IF(D20=0,65,D20) -> 84.5
A21: 10 | B21: 93 | C21: 70 | D21: =(B21+C21)/2 -> 81.5 | E21: =IF(65-D21>0,65-M21,0) -> 0 | F21: =IF((D21)-65<0,0,(D21)-65) -> 16.5 | G21: 0 | H21: 0 | I21: 16 | J21: 90 | M21: =IF(D21=0,65,D21) -> 81.5
A22: 11 | B22: 94 | C22: 65 | D22: =(B22+C22)/2 -> 79.5 | E22: =IF(65-D22>0,65-M22,0) -> 0 | F22: =IF((D22)-65<0,0,(D22)-65) -> 14.5 | G22: 0 | H22: 0 | I22: 16 | J22: 140 | M22: =IF(D22=0,65,D22) -> 79.5
A23: 12 | B23: 92 | C23: 63 | D23: =(B23+C23)/2 -> 77.5 | E23: =IF(65-D23>0,65-M23,0) -> 0 | F23: =IF((D23)-65<0,0,(D23)-65) -> 12.5 | G23: 0 | H23: 0 | I23: 20 | J23: 140 | M23: =IF(D23=0,65,D23) -> 77.5
... A42: 31 | B42: 77 | C42: 42 | D42: =(B42+C42)/2 -> 59.5 | E42: =IF(65-D42>0,65-M42,0) -> 5.5 | F42: =IF((D42)-65<0,0,(D42)-65) -> 0 | G42: 0 | H42: 0 | I42: 14 | J42: 140 | M42: =IF(D42=0,65,D42) -> 59.5
A43: TOTAL | B43: N/A | C43: N/A | D43: =SUM(D12:D42) -> 2420 | E43: =SUM(E12:E42) -> 20 | F43: =SUM(F12:F42) -> 425 | G43: =SUM(G12:G42) -> 1.48 | H43: =SUM(H12:H42) -> 0 | I43: N/A | J43: N/A | M43: =IF(D43=0,65,D43) -> 2420
A44: EXTREME | B44: =MAXA(B12:B42) -> 96 | C44: =MINA(C12:C42) -> 40 | D44: =(B44+C44)/2 -> 68 | E44: =IF(65-D44>0,65-M44,0) -> 0 | F44: =IF((D44)-65<0,0,(D44)-65) -> 3 | G44: =MAXA(G13:G42) -> 1.03 | H44: =MAXA(H13:H42) -> 0 | I44: =MAXA(I12:I42) -> 32 | J44: 300
A45: MEAN | B45: =AVERAGEA(B12:B42) -> 90.451613 | C45: =AVERAGEA(C12:C42) -> 65.677419 | D45: =(B45+C45)/2 -> 78.064516 | E45: =IF(65-D45>0,65-M45,0) -> 0 | F45: =IF((D45)-65<0,0,(D45)-65) -> 13.064516 | G45: =AVERAGEA(G12:G42) -> 0.047741935 | H45: =AVERAGEA(H12:H42) -> 0 | I45: =AVERAGEA(I12:I42) -> 19.096774 | J45: =AVERAGE(J12:J42) -> 148.70968
A46: CLIMO. | B46: 100 | C46: 26 | D46: 73 | E46: =AVERAGEA(E13:E42) -> 0.66666667 | F46: =AVERAGEA(F13:F42) -> 13.633333 | G46: 3.1 | H46: N/A | I46: 8 | J46: 160
A47: PRECIPITATION ABOVE CLIMO. | G47: =(G43-G46) -> -1.62
A48: NOTE: CLIMO. TEMPERATURES ARE EXTREMES. TEMPERATURE
B52: TEMPERATURE | G52: PRECIP. | J52: WIND
B53: EXTRME MAX | C53: MEAN MAX | D53: MEAN | E53: MEAN MIN | F53: EXTRME MIN | G53: MAX | H53: MEAN | I53: 24 HR MAX | J53: MAX
A54: FROM ABOVE | B54: =MAXA(B12:B42) -> 96 | C54: =AVERAGEA(B12:B42) -> 90.451613 | D54: =(B45+C45)/2 -> 78.064516 | E54: =AVERAGEA(C12:C42) -> 65.677419 | F54: =MINA(C12:C42) -> 40 | G54: =SUM(G12:G42) -> 1.48 | H54: =AVERAGEA(G12:G42) -> 0.047741935 | I54: =MAXA(G12:G40) -> 1.03 | J54: =MAXA(I12:I40) -> 32
A55: CLIMO | B55: 100 | C55: 84 | D55: 73 | E55: 62 | F55: 26 | G55: 13.9 | H55: 3.1 | I55: 6.5 | J55: 60

Sheet Nov
A2: 502 OSS/OSW LACKLAND AFB, KELLY ANNEX, TX
A3: DAILY CLIMATOLOGICAL DATA
A4: FOR
A5: NOVEMBER 2025
B7: TEMPERATURE | G7: PRECIPITATION | I7: WIND
D8: DEGREE DAYS | G8: WATER | H8: DAILY
D9: BASE = 65 | G9: EQUIV- | H9: SNOW | I9: MAX | J9: DIREC-
A10: DAY | B10: MAX | C10: MIN | D10: MEAN | E10: HEATING | F10: COOLING | G10: ALENT | H10: FALL | I10: SPEED | J10: TION
A12: 1 | B12: 77 | C12: 50 | D12: =(B12+C12)/2 -> 63.5 | E12: =IF(65-D12>0,65-M12,0) -> 1.5 | F12: =IF((D12)-65<0,0,(D12)-65) -> 0 | G12: 0 | H12: 0 | I12: 25 | J12: 40 | M12: =IF(D12=0,65,D12) -> 63.5
A13: 2 | B13: 75 | C13: 48 | D13: =(B13+C13)/2 -> 61.5 | E13: =IF(65-D13>0,65-M13,0) -> 3.5 | F13: =IF((D13)-65<0,0,(D13)-65) -> 0 | G13: 0 | H13: 0 | I13: 10 | J13: 30 | M13: =IF(D13=0,65,D13) -> 61.5
A14: 3 | B14: 79 | C14: 46 | D14: =(B14+C14)/2 -> 62.5 | E14: =IF(65-D14>0,65-M14,0) -> 2.5 | F14: =IF((D14)-65<0,0,(D14)-65) -> 0 | G14: 0 | H14: 0 | I14: 15 | J14: 140 | M14: =IF(D14=0,65,D14) -> 62.5
A15: 4 | B15: 81 | C15: 49 | D15: =(B15+C15)/2 -> 65 | E15: =IF(65-D15>0,65-M15,0) -> 0 | F15: =IF((D15)-65<0,0,(D15)-65) -> 0 | G15: 0 | H15: 0 | I15: 18 | J15: 190 | M15: =IF(D15=0,65,D15) -> 65
A16: 5 | B16: 85 | C16: 53 | D16: =(B16+C16)/2 -> 69 | E16: =IF(65-D16>0,65-M16,0) -> 0 | F16: =IF((D16)-65<0,0,(D16)-65) -> 4 | G16: 0 | H16: 0 | I16: 17 | J16: 210 | M16: =IF(D16=0,65,D16) -> 69
A17: 6 | B17: 86 | C17: 55 | D17: =(B17+C17)/2 -> 70.5 | E17: =IF(65-D17>0,65-M17,0) -> 0 | F17: =IF((D17)-65<0,0,(D17)-65) -> 5.5 | G17: 0 | H17: 0 | I17: 16 | J17: 160 | M17: =IF(D17=0,65,D17) -> 70.5
A18: 7 | B18: 92 | C18: 56 | D18: =(B18+C18)/2 -> 74 | E18: =IF(65-D18>0,65-M18,0) -> 0 | F18: =IF((D18)-65<0,0,(D18)-65) -> 9 | G18: 0 | H18: 0 | I18: 15 | J18: 230 | M18: =IF(D18=0,65,D18) -> 74
A19: 8 | B19: 90 | C19: 55 | D19: =(B19+C19)/2 -> 72.5 | E19: =IF(65-D19>0,65-M19,0) -> 0 | F19: =IF((D19)-65<0,0,(D19)-65) -> 7.5 | G19: 0 | H19: 0 | I19: 12 | J19: 10 | M19: =IF(D19=0,65,D19) -> 72.5
A20: 9 | B20: 75 | C20: 56 | D20: =(B20+C20)/2 -> 65.5 | E20: =IF(65-D20>0,65-M20,0) -> 0 | F20: =IF((D20)-65<0,0,(D20)-65) -> 0.5 | G20: 0 | H20: 0 | I20: 33 | J20: 10 | M20: =IF(D20=0,65,D20) -> 65.5
A21: 10 | B21: 65 | C21: 44 | D21: =(B21+C21)/2 -> 54.5 | E21: =IF(65-D21>0,65-M21,0) -> 10.5 | F21: =IF((D21)-65<0,0,(D21)-65) -> 0 | G21: 0 | H21: 0 | I21: 19 | J21: 10 | M21: =IF(D21=0,65,D21) -> 54.5
A22: 11 | B22: 75 | C22: 36 | D22: =(B22+C22)/2 -> 55.5 | E22: =IF(65-D22>0,65-M22,0) -> 9.5 | F22: =IF((D22)-65<0,0,(D22)-65) -> 0 | G22: 0 | H22: 0 | I22: 19 | J22: 170 | M22: =IF(D22=0,65,D22) -> 55.5
A23: 12 | B23: 84 | C23: 48 | D23: =(B23+C23)/2 -> 66 | E23: =IF(65-D23>0,65-M23,0) -> 0 | F23: =IF((D23)-65<0,0,(D23)-65) -> 1 | G23: 0 | H23: 0 | I23: 20 | J23: 130 | M23: =IF(D23=0,65,D23) -> 66
... A40: 29 | B40: 80 | C40: 60 | D40: =(B40+C40)/2 -> 70 | E40: =IF(65-D40>0,65-M40,0) -> 0 | F40: =IF((D40)-65<0,0,(D40)-65) -> 5 | G40: 0 | H40: 0 | I40: 21 | J40: 200 | M40: =IF(D40=0,65,D40) -> 70
A41: 30 | B41: 67 | C41: 49 | D41: =(B41+C41)/2 -> 58 | E41: =IF(65-D41>0,65-M41,0) -> 7 | F41: =IF((D41)-65<0,0,(D41)-65) -> 0 | G41: 0 | H41: 0 | M41: =IF(D41=0,65,D41) -> 58
A42: TOTAL | B42: N/A | C42: N/A | D42: =SUM(D12:D41) -> 2051 | E42: =SUM(E12:E41) -> 50 | F42: =SUM(F12:F41) -> 151 | G42: =SUM(G12:G41) -> 0.37 | H42: 0 | I42: N/A | J42: N/A | M42: =IF(D42=0,65,D42) -> 2051
A43: EXTREME | B43: =MAXA(B12:B41) -> 92 | C43: =MINA(C12:C41) -> 36 | D43: =(B43+C43)/2 -> 64 | E43: =IF(65-D43>0,65-M43,0) -> 65 | F43: =IF((D43)-65<0,0,(D43)-65) -> 0 | G43: =MAXA(G13:G41) -> 0.24 | H43: 0 | I43: =MAXA(I12:I41) -> 33 | J43: 10
A44: MEAN | B44: =AVERAGEA(B12:B41) -> 80.133333 | C44: =AVERAGEA(C12:C41) -> 56.6 | D44: =(B44+C44)/2 -> 68.366667 | E44: =IF(65-D44>0,65-M44,0) -> 0 | F44: =IF((D44)-65<0,0,(D44)-65) -> 3.3666667 | G44: =AVERAGEA(G12:G41) -> 0.012333333 | H44: =AVERAGEA(H12:H41) -> 0 | I44: =AVERAGEA(I12:I41) -> 18.758621 | J44: =AVERAGEA(J12:J41) -> 122.06897
A45: CLIMO. | B45: 93 | C45: 21 | D45: 62 | E45: =AVERAGEA(E13:E41) -> 1.6724138 | F45: =AVERAGEA(F13:F41) -> 5.2068966 | G45: 1.9 | H45: N/A | I45: 9 | J45: 10
A46: PRECIPITATION ABOVE CLIMO. | G46: =(G42-G45) -> -1.53
A47: NOTE: CLIMO. TEMPERATURES ARE EXTREMES.
B51: TEMPERATURE | G51: PRECIP. | J51: WIND
B52: EXTRME MAX | C52: MEAN MAX | D52: MEAN | E52: MEAN MIN | F52: EXTRME MIN | G52: MAX | H52: MEAN | I52: 24 HR MAX | J52: MAX
A53: FROM ABOVE | B53: =MAXA(B11:B41) -> 92 | C53: =AVERAGEA(B11:B41) -> 80.133333 | D53: =(B44+C44)/2 -> 68.366667 | E53: =AVERAGEA(C11:C41) -> 56.6 | F53: =MINA(C11:C41) -> 36 | G53: =SUM(G11:G41) -> 0.37 | H53: =AVERAGEA(G11:G41) -> 0.012333333 | I53: =MAXA(G11:G39) -> 0.24 | J53: =MAXA(I11:I39) -> 33
A54: CLIMO | B54: 93 | C54: 73 | D54: 62 | E54: 52 | F54: 21 | G54: 10.7 | H54: 1.9 | I54: 4.3 | J54: 59

Sheet Dec
A2: 502 OSS/OSW LACKLAND AFB, KELLY ANNEX, TX
A3: DAILY CLIMATOLOGICAL DATA
A4: FOR
A5: DECEMBER 2025
B7: TEMPERATURE | G7: PRECIPITATION | I7: WIND
D8: DEGREE DAYS | G8: WATER | H8: DAILY
D9: BASE = 65 | G9: EQUIV- | H9: SNOW | I9: MAX | J9: DIREC-
A10: DAY | B10: MAX | C10: MIN | D10: MEAN | E10: HEATING | F10: COOLING | G10: ALENT | H10: FALL | I10: SPEED | J10: TION
A12: 1 | B12: 52 | C12: 42 | D12: =(B12+C12)/2 -> 47 | E12: =IF(65-D12>0,65-M12,0) -> 18 | F12: =IF((D12)-65<0,0,(D12)-65) -> 0 | G12: 0 | H12: 0 | I12: 19 | J12: 20 | M12: =IF(D12=0,65,D12) -> 47
A13: 2 | B13: 57 | C13: 37 | D13: =(B13+C13)/2 -> 47 | E13: =IF(65-D13>0,65-M13,0) -> 18 | F13: =IF((D13)-65<0,0,(D13)-65) -> 0 | G13: 0 | H13: 0 | I13: 14 | J13: 10 | M13: =IF(D13=0,65,D13) -> 47
A14: 3 | B14: 59 | C14: 36 | D14: =(B14+C14)/2 -> 47.5 | E14: =IF(65-D14>0,65-M14,0) -> 17.5 | F14: =IF((D14)-65<0,0,(D14)-65) -> 0 | G14: 0 | H14: 0 | I14: 10 | J14: 40 | M14: =IF(D14=0,65,D14) -> 47.5
A15: 4 | B15: 58 | C15: 47 | D15: =(B15+C15)/2 -> 52.5 | E15: =IF(65-D15>0,65-M15,0) -> 12.5 | F15: =IF((D15)-65<0,0,(D15)-65) -> 0 | G15: 0.03 | H15: 0 | I15: 25 | J15: 360 | M15: =IF(D15=0,65,D15) -> 52.5
A16: 5 | B16: 56 | C16: 46 | D16: =(B16+C16)/2 -> 51 | E16: =IF(65-D16>0,65-M16,0) -> 14 | F16: =IF((D16)-65<0,0,(D16)-65) -> 0 | G16: 0 | H16: 0 | I16: 13 | J16: 150 | M16: =IF(D16=0,65,D16) -> 51
A17: 6 | B17: 79 | C17: 47 | D17: =(B17+C17)/2 -> 63 | E17: =IF(65-D17>0,65-M17,0) -> 2 | F17: =IF((D17)-65<0,0,(D17)-65) -> 0 | G17: 0 | H17: 0 | I17: 13 | J17: 170 | M17: =IF(D17=0,65,D17) -> 63
A18: 7 | B18: 82 | C18: 54 | D18: =(B18+C18)/2 -> 68 | E18: =IF(65-D18>0,65-M18,0) -> 0 | F18: =IF((D18)-65<0,0,(D18)-65) -> 3 | G18: 0 | H18: 0 | I18: 26 | J18: 330 | M18: =IF(D18=0,65,D18) -> 68
A19: 8 | B19: 66 | C19: 39 | D19: =(B19+C19)/2 -> 52.5 | E19: =IF(65-D19>0,65-M19,0) -> 12.5 | F19: =IF((D19)-65<0,0,(D19)-65) -> 0 | G19: 0 | H19: 0 | I19: 17 | J19: 350 | M19: =IF(D19=0,65,D19) -> 52.5
A20: 9 | B20: 69 | C20: 32 | D20: =(B20+C20)/2 -> 50.5 | E20: =IF(65-D20>0,65-M20,0) -> 14.5 | F20: =IF((D20)-65<0,0,(D20)-65) -> 0 | G20: 0 | H20: 0 | I20: 15 | J20: 200 | M20: =IF(D20=0,65,D20) -> 50.5
A21: 10 | B21: 77 | C21: 40 | D21: =(B21+C21)/2 -> 58.5 | E21: =IF(65-D21>0,65-M21,0) -> 6.5 | F21: =IF((D21)-65<0,0,(D21)-65) -> 0 | G21: 0 | H21: 0 | I21: 20 | J21: 60 | M21: =IF(D21=0,65,D21) -> 58.5
A22: 11 | B22: 71 | C22: 38 | D22: =(B22+C22)/2 -> 54.5 | E22: =IF(65-D22>0,65-M22,0) -> 10.5 | F22: =IF((D22)-65<0,0,(D22)-65) -> 0 | G22: 0 | H22: 0 | I22: 12 | J22: 210 | M22: =IF(D22=0,65,D22) -> 54.5
A23: 12 | B23: 77 | C23: 50 | D23: =(B23+C23)/2 -> 63.5 | E23: =IF(65-D23>0,65-M23,0) -> 1.5 | F23: =IF((D23)-65<0,0,(D23)-65) -> 0 | G23: 0 | H23: 0 | I23: 11 | J23: 240 | M23: =IF(D23=0,65,D23) -> 63.5
... A42: 31 | B42: 70 | C42: 34 | D42: =(B42+C42)/2 -> 52 | E42: =IF(65-D42>0,65-M42,0) -> 13 | F42: =IF((D42)-65<0,0,(D42)-65) -> 0 | G42: 0 | H42: 0 | I42: 13 | J42: 240 | M42: =IF(D42=0,65,D42) -> 52
A43: TOTAL | B43: N/A | C43: N/A | D43: =SUM(D12:D42) -> 1854.5 | E43: =SUM(E12:E42) -> 226 | F43: =SUM(F12:F42) -> 65.5 | G43: =SUM(G12:G42) -> 0.35 | H43: =SUM(H12:H42) -> 0 | I43: N/A | J43: N/A | M43: =IF(D43=0,65,D43) -> 1854.5
A44: EXTREME | B44: =MAXA(B13:B42) -> 83 | C44: =MINA(C12:C42) -> 32 | D44: =(B44+C44)/2 -> 57.5 | E44: =IF(65-D44>0,65-M44,0) -> 65 | F44: =IF((D44)-65<0,0,(D44)-65) -> 0 | G44: =MAXA(G13:G42) -> 0.18 | H44: =MAXA(H13:H42) -> 0 | I44: =MAXA(I12:I42) -> 36 | J44: 20
A45: MEAN | B45: =AVERAGEA(B12:B42) -> 70.774194 | C45: =AVERAGEA(C12:C42) -> 48.870968 | D45: =(B45+C45)/2 -> 59.822581 | E45: =IF(65-D45>0,65-M45,0) -> 65 | F45: =IF((D45)-65<0,0,(D45)-65) -> 0 | G45: =AVERAGEA(G12:G42) -> 0.011290323 | H45: =AVERAGEA(H12:H42) -> 0 | I45: =AVERAGEA(I12:I42) -> 17.16129 | J45: =AVERAGE(J12:J42) -> 160.64516
A46: CLIMO. | B46: 89 | C46: 9 | D46: 57 | E46: =AVERAGEA(E13:E42) -> 6.9333333 | F46: =AVERAGEA(F13:F42) -> 2.1833333 | G46: 1.4 | H46: N/A | I46: 9 | J46: 10
A47: PRECIPITATION ABOVE CLIMO. | G47: =(G43-G46) -> -1.05
A48: NOTE: CLIMO. TEMPERATURES ARE EXTREMES.
B52: TEMPERATURE | G52: PRECIP. | J52: WIND
B53: EXTRME MAX | C53: MEAN MAX | D53: MEAN | E53: MEAN MIN | F53: EXTRME MIN | G53: MAX | H53: MEAN | I53: 24 HR MAX | J53: MAX
A54: FROM ABOVE | B54: =MAXA(B12:B42) -> 83 | C54: =AVERAGEA(B12:B42) -> 70.774194 | D54: =(B45+C45)/2 -> 59.822581 | E54: =AVERAGEA(C12:C42) -> 48.870968 | F54: =MINA(C12:C42) -> 32 | G54: =SUM(G12:G42) -> 0.35 | H54: =AVERAGEA(G12:G42) -> 0.011290323 | I54: =MAXA(G12:G42) -> 0.18 | J54: =MAXA(I12:I42) -> 36
A55: CLIMO | B55: 89 | C55: 68 | D55: 57 | E55: 47 | F55: 9 | G55: 11.6 | H55: 1.4 | I55: 4.7 | J55: 79

Sheet Year 2025
B1: 502 OSS/OSW LACKLAND AFB, KELLY ANNEX, TX
B3: MONTHLY AND ANNUAL CLIMATOLOGICAL DATA
B4: FOR
B5: THE YEAR OF 2025
B8: TEMPERATURE | G8: DEGREE DAYS | I8: PRECIPITATION | L8: WIND
I10: WATER | K10: SOLID | L10: MAX
B11: EXTREM | C11: AVG | D11: MEAN | E11: AVG | F11: EXTREM | G11: HEATING | H11: COOLING | I11: EQUIV- | J11: 24 HOUR | K11: PRECIP | L11: SPEED | M11: DIREC
A12: MONTH | B12: MAX | C12: MAX | E12: MIN | F12: MIN | I12: ALENT | J12: MAX | K12: FALL | L12: KTS | M12: TION
A14: JAN | B14: =SUM(Jan!B44) -> 79 | C14: =SUM(Jan!B45) -> 59.774194 | D14: =SUM(Jan!D45) -> 50 | E14: =SUM(Jan!C45) -> 40.225806 | F14: =SUM(Jan!C44) -> 23 | G14: =SUM(Jan!E12:E42) -> 468 | H14: =SUM(Jan!F12:F42) -> 3 | I14: =SUM(Jan!G43) -> 0.91 | J14: =SUM(Jan!G12:G42) -> 0.91 | K14: 0 | L14: =SUM(Jan!I44) -> 33 | M14: =Jan!$J$44 -> 340
A16: FEB | B16: =SUM('Feb '!B42) -> 91 | C16: =SUM('Feb '!B43) -> 69.071429 | D16: =SUM('Feb '!D43) -> 57.732143 | E16: =SUM('Feb '!C43) -> 46.392857 | F16: =SUM('Feb '!C42) -> 23 | G16: =SUM('Feb '!E12:E40) -> 261.5 | H16: =SUM('Feb '!F12:F40) -> 70.5 | I16: =SUM('Feb '!G41) -> 0.4 | J16: =MAXA('Feb '!G12:G40) -> 0.24 | K16: 0 | L16: =SUM('Feb '!I42) -> 33 | M16: ='Feb '!$J$42 -> 360
A18: MAR | B18: =SUM(Mar!B44) -> 97 | C18: =SUM(Mar!B45) -> 83.870968 | D18: =SUM(Mar!D45) -> 69.806452 | E18: =SUM(Mar!C45) -> 55.741935 | F18: =SUM(Mar!C44) -> 38 | G18: =SUM(Mar!E12:E42) -> 29.5 | H18: =SUM(Mar!F12:F42) -> 178.5 | I18: =SUM(Mar!G43) -> 2.59 | J18: =MAXA(Mar!G12:G42) -> 1.04 | K18: =SUM(Mar!H43) -> 0 | L18: =SUM(Mar!I44) -> 41 | M18: =Mar!$J$44 -> 290
A20: APR | B20: =SUM('Apr '!B43) -> 94 | C20: =SUM('Apr '!B44) -> 86.5 | D20: =SUM('Apr '!D44) -> 75.216667 | E20: =SUM('Apr '!C44) -> 63.933333 | F20: =SUM('Apr '!C43) -> 40 | G20: =SUM('Apr '!E12:E41) -> 21 | H20: =SUM('Apr '!F12:F41) -> 327.5 | I20: =SUM('Apr '!G42) -> 1.16 | J20: =MAXA('Apr '!G12:G41) -> 0.8 | K20: =SUM('Apr '!H42) -> 0 | L20: =SUM('Apr '!I43) -> 33 | M20: ='Apr '!$J$43 -> 340
A22: MAY | B22: =May!$B$43 -> 104 | C22: =May!$B$44 -> 93.451613 | D22: =May!$D$44 -> 81.774194 | E22: =May!$C$44 -> 70.096774 | F22: =May!$C$43 -> 53 | G22: =SUM(May!E12:E42) -> 0 | H22: =SUM(May!F12:F42) -> 1022.5 | I22: =SUM(May!$G$42) -> 2.12 | J22: =(May!G43) -> 1.58 | K22: =May!$H$42 -> 0 | L22: =May!$I$43 -> 36 | M22: =May!$J$43 -> 150
